Workbook

Sheet PRICING
A2: SMDI
A3: UPDATE: OCTBER 13, 2025 11:30 AM BY: I.T. DEPT.
A4: D.Price | B4: BRAND/MODEL | C4: DP | D4: 6 | E4: 12 | F4: 18 | G4: 24 | H4: 30 | I4: 36 | K4: LCP | L4: COD | M4: 30 Days | N4: 60 Days | O4: 90 Days | P4: I.R. ( + ) | R4: 6 | S4: 12-36 | U4: Rebate | W4: DATE | X4: MB
C5: BELOW
A6: SUZUKI
A7: 84900 | B7: ACCESS 125 (UZ125NEY) | C7: 20000 | D7: =IF(C7>=1,(K7-C7)*(1+P7*$D$4/100)/$D$4+Q7+R7,"") -> 12975.487 | E7: =IF(C7>=1,(K7-C7)*(1+P7*$E$4/100)/$E$4+Q7+S7,"") -> 7220.7369 | F7: =IF(C7>=1,(K7-C7)*(1+$P7*$F$4/100)/$F$4+Q7+S7, "") -> 5344.1536 | G7: =IF(C7>=1, (K7-C7)*(1+$P7*$G$4/100)/$G$4+Q7+S7,"") -> 4405.8619 | H7: =IF(C7>=1, (K7-C7)*(1+$P7*$H$4/100)/$H$4+Q7+S7, "") -> 3842.8869 | I7: =IF(C7>=1, (K7-C7)*(1+$P7*$I$4/100)/$I$4+Q7+S7, "") -> 3467.5702 | K7: 87557 | L7: 86454 | M7: =86822+1200 -> 88022 | N7: =87189+1200 -> 88389 | O7: =87557+1100 -> 88657 | P7: 2.17 | R7: 250 | S7: 125 | U7: 200 | V7: 100 | W7: 45918 | X7: MB-2025-042
A8: 93900 | B8: ACCESS 125 RIDE CONNECT EDITION (UZ125NES) | C8: 20000 | D8: =IF(C8>=1,(K8-C8)*(1+P8*$D$4/100)/$D$4+Q8+R8,"") -> 14721.646 | E8: =IF(C8>=1,(K8-C8)*(1+P8*$E$4/100)/$E$4+Q8+S8,"") -> 8194.3959 | F8: =IF(C8>=1,(K8-C8)*(1+$P8*$F$4/100)/$F$4+Q8+S8, "") -> 6060.3126 | G8: =IF(C8>=1, (K8-C8)*(1+$P8*$G$4/100)/$G$4+Q8+S8,"") -> 4993.2709 | H8: =IF(C8>=1, (K8-C8)*(1+$P8*$H$4/100)/$H$4+Q8+S8, "") -> 4353.0459 | I8: =IF(C8>=1, (K8-C8)*(1+$P8*$I$4/100)/$I$4+Q8+S8, "") -> 3926.2292 | K8: =96827 -> 96827 | L8: =95419 -> 95419 | M8: =95888+1200 -> 97088 | N8: =96358+1200 -> 97558 | O8: =96827+1100 -> 97927 | P8: 2.17 | R8: 250 | S8: 125 | U8: 200 | V8: 100 | W8: 45918 | X8: MB-2025-043
A9: 66900 | B9: ADDRESS (UK110NE/NZ/NX) | D9: =IF(C9>=1,(K9-C9)*(1+P9*$D$4/100)/$D$4+Q9+R9,"") | E9: =IF(C9>=1,(K9-C9)*(1+P9*$E$4/100)/$E$4+Q9+S9,"") | F9: =IF(C9>=1,(K9-C9)*(1+$P9*$F$4/100)/$F$4+Q9+S9, "") | G9: =IF(C9>=1, (K9-C9)*(1+$P9*$G$4/100)/$G$4+Q9+S9,"") | H9: =IF(C9>=1, (K9-C9)*(1+$P9*$H$4/100)/$H$4+Q9+S9, "") | I9: =IF(C9>=1, (K9-C9)*(1+$P9*$I$4/100)/$I$4+Q9+S9, "") | K9: 70694 | L9: 68026 | M9: =69875+240 -> 70115 | N9: =70764+240 -> 71004 | O9: =71554+240 -> 71794 | P9: 2.17 | R9: 250 | S9: 125 | U9: 200 | V9: 100
A10: 80400 | B10: AVENIS (UN125NE) | D10: =IF(C10>=1,(K10-C10)*(1+P10*$D$4/100)/$D$4+Q10+R10,"") | E10: =IF(C10>=1,(K10-C10)*(1+P10*$E$4/100)/$E$4+Q10+S10,"") | F10: =IF(C10>=1,(K10-C10)*(1+$P10*$F$4/100)/$F$4+Q10+S10, "") | G10: =IF(C10>=1, (K10-C10)*(1+$P10*$G$4/100)/$G$4+Q10+S10,"") | H10: =IF(C10>=1, (K10-C10)*(1+$P10*$H$4/100)/$H$4+Q10+S10, "") | I10: =IF(C10>=1, (K10-C10)*(1+$P10*$I$4/100)/$I$4+Q10+S10, "") | K10: =84878 -> 84878 | L10: =81499 -> 81499 | M10: =82625+1200 -> 83825 | N10: =83751+1200 -> 84951 | O10: =84878+1100 -> 85978 | P10: 2.17 | R10: 250 | S10: 125 | U10: 200 | V10: 100 | W10: 10/31/2023 | X10: MB-2023-113
A11: 83400 | B11: BURGMAN STREET (UB125 NMB / NMX / NM-9) | D11: =IF(C11>=1,(K11-C11)*(1+P11*$D$4/100)/$D$4+Q11+R11,"") | E11: =IF(C11>=1,(K11-C11)*(1+P11*$E$4/100)/$E$4+Q11+S11,"") | F11: =IF(C11>=1,(K11-C11)*(1+$P11*$F$4/100)/$F$4+Q11+S11, "") | G11: =IF(C11>=1, (K11-C11)*(1+$P11*$G$4/100)/$G$4+Q11+S11,"") | H11: =IF(C11>=1, (K11-C11)*(1+$P11*$H$4/100)/$H$4+Q11+S11, "") | I11: =IF(C11>=1, (K11-C11)*(1+$P11*$I$4/100)/$I$4+Q11+S11, "") | K11: =87306 -> 87306 | L11: =84432 -> 84432 | M11: =85390+1200 -> 86590 | N11: =86348+1200 -> 87548 | O11: =87306+1100 -> 88406 | P11: 2.17 | R11: 250 | S11: 125 | U11: 200 | V11: 100 | W11: 10/31/2023 | X11: MB-2023-114
A12: 92400 | B12: BURGMAN STREET 125 EX (UB125LNM) | D12: =IF(C12>=1,(K12-C12)*(1+P12*$D$4/100)/$D$4+Q12+R12,"") | E12: =IF(C12>=1,(K12-C12)*(1+P12*$E$4/100)/$E$4+Q12+S12,"") | F12: =IF(C12>=1,(K12-C12)*(1+$P12*$F$4/100)/$F$4+Q12+S12, "") | G12: =IF(C12>=1, (K12-C12)*(1+$P12*$G$4/100)/$G$4+Q12+S12,"") | H12: =IF(C12>=1, (K12-C12)*(1+$P12*$H$4/100)/$H$4+Q12+S12, "") | I12: =IF(C12>=1, (K12-C12)*(1+$P12*$I$4/100)/$I$4+Q12+S12, "") | K12: =95262 -> 95262 | L12: =92400 -> 92400 | M12: =93354+1200 -> 94554 | N12: =94308+1200 -> 95508 | O12: =95262+1100 -> 96362 | P12: 2.17 | R12: 250 | S12: 125 | U12: 200 | V12: 100 | W12: 04/14/2023 | X12: MB-2023-078
A13: 48900 | B13: GD110 | D13: =IF(C13>=1,(K13-C13)*(1+P13*$D$4/100)/$D$4+Q13+R13,"") | E13: =IF(C13>=1,(K13-C13)*(1+P13*$E$4/100)/$E$4+Q13+S13,"") | F13: =IF(C13>=1,(K13-C13)*(1+$P13*$F$4/100)/$F$4+Q13+S13, "") | G13: =IF(C13>=1, (K13-C13)*(1+$P13*$G$4/100)/$G$4+Q13+S13,"") | H13: =IF(C13>=1, (K13-C13)*(1+$P13*$H$4/100)/$H$4+Q13+S13, "") | I13: =IF(C13>=1, (K13-C13)*(1+$P13*$I$4/100)/$I$4+Q13+S13, "") | K13: 52555 | L13: 51573 | M13: =52800+60+240 -> 53100 | N13: =53127+60+240 -> 53427 | O13: =53355+60+240 -> 53655 | P13: 3 | R13: 250 | S13: 125 | U13: 500 | V13: 50
A14: 91900 | B14: GIXXER (GSX150RZA_fi) | D14: =IF(C14>=1,(K14-C14)*(1+P14*$D$4/100)/$D$4+Q14+R14,"") | E14: =IF(C14>=1,(K14-C14)*(1+P14*$E$4/100)/$E$4+Q14+S14,"") | F14: =IF(C14>=1,(K14-C14)*(1+$P14*$F$4/100)/$F$4+Q14+S14, "") | G14: =IF(C14>=1, (K14-C14)*(1+$P14*$G$4/100)/$G$4+Q14+S14,"") | H14: =IF(C14>=1, (K14-C14)*(1+$P14*$H$4/100)/$H$4+Q14+S14, "") | I14: =IF(C14>=1, (K14-C14)*(1+$P14*$I$4/100)/$I$4+Q14+S14, "") | K14: 94597 | L14: 92795 | M14: =93395+1200 -> 94595 | N14: =93996+1200 -> 95196 | O14: =94597+1100 -> 95697 | P14: 2.17 | R14: 250 | S14: 125 | U14: 200 | V14: 100
A15: 93900 | B15: GIXXER (GSX150RF ) | D15: =IF(C15>=1,(K15-C15)*(1+P15*$D$4/100)/$D$4+Q15+R15,"") | E15: =IF(C15>=1,(K15-C15)*(1+P15*$E$4/100)/$E$4+Q15+S15,"") | F15: =IF(C15>=1,(K15-C15)*(1+$P15*$F$4/100)/$F$4+Q15+S15, "") | G15: =IF(C15>=1, (K15-C15)*(1+$P15*$G$4/100)/$G$4+Q15+S15,"") | H15: =IF(C15>=1, (K15-C15)*(1+$P15*$H$4/100)/$H$4+Q15+S15, "") | I15: =IF(C15>=1, (K15-C15)*(1+$P15*$I$4/100)/$I$4+Q15+S15, "") | K15: 96597 | L15: 94795 | M15: =95395+1200 -> 96595 | N15: =95996+1200 -> 97196 | O15: =96597+1100 -> 97697 | P15: 2.17 | R15: 250 | S15: 125 | U15: 200 | V15: 100 | W15: 08/29/20 | X15: 2020-31
A16: 104900 | B16: GIXXER 150FI (GSX150RFZ / RF-6 / RF-8 ) 50% | D16: =IF(C16>=1,(K16-C16)*(1+P16*$D$4/100)/$D$4+Q16+R16,"") | E16: =IF(C16>=1,(K16-C16)*(1+P16*$E$4/100)/$E$4+Q16+S16,"") | F16: =IF(C16>=1,(K16-C16)*(1+$P16*$F$4/100)/$F$4+Q16+S16, "") | G16: =IF(C16>=1, (K16-C16)*(1+$P16*$G$4/100)/$G$4+Q16+S16,"") | H16: =IF(C16>=1, (K16-C16)*(1+$P16*$H$4/100)/$H$4+Q16+S16, "") | I16: =IF(C16>=1, (K16-C16)*(1+$P16*$I$4/100)/$I$4+Q16+S16, "") | K16: =108689 -> 108689 | L16: =106887 -> 106887 | M16: =107487+1200 -> 108687 | N16: =108088+1200 -> 109288 | O16: =108689+1100 -> 109789 | P16: 2.17 | R16: 250 | S16: 125 | U16: 200 | V16: 100 | W16: 10/31/2024 | X16: MB-MKTG2024-31
A17: 114900 | B17: GIXXER SF155 SPORTS FULL-FAIRED (GSX150FRFX-8/FRF-8) 50% | D17: =IF(C17>=1,(K17-C17)*(1+P17*$D$4/100)/$D$4+Q17+R17,"") | E17: =IF(C17>=1,(K17-C17)*(1+P17*$E$4/100)/$E$4+Q17+S17,"") | F17: =IF(C17>=1,(K17-C17)*(1+$P17*$F$4/100)/$F$4+Q17+S17, "") | G17: =IF(C17>=1, (K17-C17)*(1+$P17*$G$4/100)/$G$4+Q17+S17,"") | H17: =IF(C17>=1, (K17-C17)*(1+$P17*$H$4/100)/$H$4+Q17+S17, "") | I17: =IF(C17>=1, (K17-C17)*(1+$P17*$I$4/100)/$I$4+Q17+S17, "") | K17: 116878 | L17: =114900 -> 114900 | M17: =115560+1200 -> 116760 | N17: =116219+1200 -> 117419 | O17: =116878+1100 -> 117978 | P17: 2.17 | R17: 250 | S17: 125 | U17: 200 | V17: 100 | W17: 10/31/2024 | X17: MB-2024-030
A18: 192900 | B18: GIXXER SF250 (GSX250FRLX/FRLZ ) NEW 50% | D18: =IF(C18>=1,(K18-C18)*(1+P18*$D$4/100)/$D$4+Q18+R18,"") | E18: =IF(C18>=1,(K18-C18)*(1+P18*$E$4/100)/$E$4+Q18+S18,"") | F18: =IF(C18>=1,(K18-C18)*(1+$P18*$F$4/100)/$F$4+Q18+S18, "") | G18: =IF(C18>=1, (K18-C18)*(1+$P18*$G$4/100)/$G$4+Q18+S18,"") | H18: =IF(C18>=1, (K18-C18)*(1+$P18*$H$4/100)/$H$4+Q18+S18, "") | I18: =IF(C18>=1, (K18-C18)*(1+$P18*$I$4/100)/$I$4+Q18+S18, "") | K18: =200824 -> 200824 | L18: 193492 | M18: =195936+1200 -> 197136 | N18: =198380+1200 -> 199580 | O18: =200824+1100 -> 201924 | P18: 2.17 | R18: 250 | S18: 125 | U18: 500 | V18: 100 | W18: 10/31/2023 | X18: MB-2023-116
A19: 182900 | B19: GIXXER250 (GSX250RL / RL-6) NEW 50% | D19: =IF(C19>=1,(K19-C19)*(1+P19*$D$4/100)/$D$4+Q19+R19,"") | E19: =IF(C19>=1,(K19-C19)*(1+P19*$E$4/100)/$E$4+Q19+S19,"") | F19: =IF(C19>=1,(K19-C19)*(1+$P19*$F$4/100)/$F$4+Q19+S19, "") | G19: =IF(C19>=1, (K19-C19)*(1+$P19*$G$4/100)/$G$4+Q19+S19,"") | H19: =IF(C19>=1, (K19-C19)*(1+$P19*$H$4/100)/$H$4+Q19+S19, "") | I19: =IF(C19>=1, (K19-C19)*(1+$P19*$I$4/100)/$I$4+Q19+S19, "") | K19: =189492 -> 189492 | L19: =183492 -> 183492 | M19: =185425+1200 -> 186625 | N19: =187358+1200 -> 188558 | O19: =189292+1100 -> 190392 | P19: 2.17 | R19: 250 | S19: 125 | U19: 500 | V19: 100 | W19: 10/31/2023 | X19: MB-2023-117
A20: 156000 | B20: GSX - R150 50% DP | D20: =IF(C20>=1,(K20-C20)*(1+P20*$D$4/100)/$D$4+Q20+R20,"") | E20: =IF(C20>=1,(K20-C20)*(1+P20*$E$4/100)/$E$4+Q20+S20,"") | F20: =IF(C20>=1,(K20-C20)*(1+$P20*$F$4/100)/$F$4+Q20+S20, "") | G20: =IF(C20>=1, (K20-C20)*(1+$P20*$G$4/100)/$G$4+Q20+S20,"") | H20: =IF(C20>=1, (K20-C20)*(1+$P20*$H$4/100)/$H$4+Q20+S20, "") | I20: =IF(C20>=1, (K20-C20)*(1+$P20*$I$4/100)/$I$4+Q20+S20, "") | K20: 162285 | L20: 157777 | M20: 160239 | N20: =161742+260 -> 162002 | O20: =163145+260 -> 163405 | P20: 2.5 | R20: 250 | S20: 125 | U20: 300 | V20: 100
A21: 112800 | B21: GSX - S150 50% DP | D21: =IF(C21>=1,(K21-C21)*(1+P21*$D$4/100)/$D$4+Q21+R21,"") | E21: =IF(C21>=1,(K21-C21)*(1+P21*$E$4/100)/$E$4+Q21+S21,"") | F21: =IF(C21>=1,(K21-C21)*(1+$P21*$F$4/100)/$F$4+Q21+S21, "") | G21: =IF(C21>=1, (K21-C21)*(1+$P21*$G$4/100)/$G$4+Q21+S21,"") | H21: =IF(C21>=1, (K21-C21)*(1+$P21*$H$4/100)/$H$4+Q21+S21, "") | I21: =IF(C21>=1, (K21-C21)*(1+$P21*$I$4/100)/$I$4+Q21+S21, "") | K21: 119362 | L21: 116046 | M21: =118111+240 -> 118351 | N21: =119217+240 -> 119457 | O21: =120222+240 -> 120462 | P21: 2.5 | R21: 250 | S21: 125 | U21: 300 | V21: 100
A22: 133900 | B22: GSX - S150MFX 50% DP | D22: =IF(C22>=1,(K22-C22)*(1+P22*$D$4/100)/$D$4+Q22+R22,"") | E22: =IF(C22>=1,(K22-C22)*(1+P22*$E$4/100)/$E$4+Q22+S22,"") | F22: =IF(C22>=1,(K22-C22)*(1+$P22*$F$4/100)/$F$4+Q22+S22, "") | G22: =IF(C22>=1, (K22-C22)*(1+$P22*$G$4/100)/$G$4+Q22+S22,"") | H22: =IF(C22>=1, (K22-C22)*(1+$P22*$H$4/100)/$H$4+Q22+S22, "") | I22: =IF(C22>=1, (K22-C22)*(1+$P22*$I$4/100)/$I$4+Q22+S22, "") | K22: =139045 -> 139045 | L22: =134492 -> 134492 | M22: =136009+1200 -> 137209 | N22: =137527+1200 -> 138727 | O22: =139045+1100 -> 140145 | P22: 2.5 | R22: 250 | S22: 125 | U22: 300 | V22: 100 | W22: 03/01/2023 | X22: MB-2023-066
A23: 93900 | B23: RAIDER150 (FU150SCD2) | D23: =IF(C23>=1,(K23-C23)*(1+P23*$D$4/100)/$D$4+Q23+R23,"") | E23: =IF(C23>=1,(K23-C23)*(1+P23*$E$4/100)/$E$4+Q23+S23,"") | F23: =IF(C23>=1,(K23-C23)*(1+$P23*$F$4/100)/$F$4+Q23+S23, "") | G23: =IF(C23>=1, (K23-C23)*(1+$P23*$G$4/100)/$G$4+Q23+S23,"") | H23: =IF(C23>=1, (K23-C23)*(1+$P23*$H$4/100)/$H$4+Q23+S23, "") | I23: =IF(C23>=1, (K23-C23)*(1+$P23*$I$4/100)/$I$4+Q23+S23, "") | K23: 101703 | L23: 94600 | M23: =96968+1200 -> 98168 | N23: =99336+1200 -> 100536 | O23: =101703+1100 -> 102803 | P23: 3 | R23: 250 | S23: 125 | U23: 500 | V23: 100
A24: 95900 | B24: RAIDER150 (FU150SCD2)RELO&MGP ED. | D24: =IF(C24>=1,(K24-C24)*(1+P24*$D$4/100)/$D$4+Q24+R24,"") | E24: =IF(C24>=1,(K24-C24)*(1+P24*$E$4/100)/$E$4+Q24+S24,"") | F24: =IF(C24>=1,(K24-C24)*(1+$P24*$F$4/100)/$F$4+Q24+S24, "") | G24: =IF(C24>=1, (K24-C24)*(1+$P24*$G$4/100)/$G$4+Q24+S24,"") | H24: =IF(C24>=1, (K24-C24)*(1+$P24*$H$4/100)/$H$4+Q24+S24, "") | I24: =IF(C24>=1, (K24-C24)*(1+$P24*$I$4/100)/$I$4+Q24+S24, "") | K24: 103703 | L24: 93800 | M24: =99928+240 -> 100168 | N24: =102296+240 -> 102536 | O24: =104563+240 -> 104803 | P24: 2.17 | R24: 250 | S24: 125 | U24: 500 | V24: 100
A25: 96900 | B25: RAIDER150 (FU150DX2-MBLACK)NEW | D25: =IF(C25>=1,(K25-C25)*(1+P25*$D$4/100)/$D$4+Q25+R25,"") | E25: =IF(C25>=1,(K25-C25)*(1+P25*$E$4/100)/$E$4+Q25+S25,"") | F25: =IF(C25>=1,(K25-C25)*(1+$P25*$F$4/100)/$F$4+Q25+S25, "") | G25: =IF(C25>=1, (K25-C25)*(1+$P25*$G$4/100)/$G$4+Q25+S25,"") | H25: =IF(C25>=1, (K25-C25)*(1+$P25*$H$4/100)/$H$4+Q25+S25, "") | I25: =IF(C25>=1, (K25-C25)*(1+$P25*$I$4/100)/$I$4+Q25+S25, "") | K25: 104703 | L25: 97600 | M25: =99967+1200 -> 101167 | N25: =102335+1200 -> 103535 | O25: =104703+1100 -> 105803 | P25: 2.17 | R25: 250 | S25: 125 | U25: 500 | V25: 100
A26: 118400 | B26: RAIDER R150_fi (FU150 MFQ/MFJ/MFX/MFZ)50% | D26: =IF(C26>=1,(K26-C26)*(1+P26*$D$4/100)/$D$4+Q26+R26,"") | E26: =IF(C26>=1,(K26-C26)*(1+P26*$E$4/100)/$E$4+Q26+S26,"") | F26: =IF(C26>=1,(K26-C26)*(1+$P26*$F$4/100)/$F$4+Q26+S26, "") | G26: =IF(C26>=1, (K26-C26)*(1+$P26*$G$4/100)/$G$4+Q26+S26,"") | H26: =IF(C26>=1, (K26-C26)*(1+$P26*$H$4/100)/$H$4+Q26+S26, "") | I26: =IF(C26>=1, (K26-C26)*(1+$P26*$I$4/100)/$I$4+Q26+S26, "") | K26: =123210 -> 123210 | L26: =118992 -> 118992 | M26: =120398+1200 -> 121598 | N26: =121804+1200 -> 123004 | O26: =123210+1100 -> 124310 | P26: 2.17 | R26: 250 | S26: 125 | U26: 500 | V26: 100 | W26: 05/31/2023 | X26: MB-2023-091
A27: 121900 | B27: RAIDER R150_fi Rugged & Sport Edition(FU150 MFX-8/MFZ-8/MFS-8) 50% | D27: =IF(C27>=1,(K27-C27)*(1+P27*$D$4/100)/$D$4+Q27+R27,"") | E27: =IF(C27>=1,(K27-C27)*(1+P27*$E$4/100)/$E$4+Q27+S27,"") | F27: =IF(C27>=1,(K27-C27)*(1+$P27*$F$4/100)/$F$4+Q27+S27, "") | G27: =IF(C27>=1, (K27-C27)*(1+$P27*$G$4/100)/$G$4+Q27+S27,"") | H27: =IF(C27>=1, (K27-C27)*(1+$P27*$H$4/100)/$H$4+Q27+S27, "") | I27: =IF(C27>=1, (K27-C27)*(1+$P27*$I$4/100)/$I$4+Q27+S27, "") | K27: =126710 -> 126710 | L27: =122492 -> 122492 | M27: =123898+1200 -> 125098 | N27: =125304+1200 -> 126504 | O27: =126710+1100 -> 127810 | P27: 2.17 | R27: 250 | S27: 125 | U27: 500 | V27: 100 | W27: 07/01/2024 | X27: MB-2024-023
A28: 108900 | B28: RAIDER150 (FU150CD3-7)NEW | D28: =IF(C28>=1,(K28-C28)*(1+P28*$D$4/100)/$D$4+Q28+R28,"") | E28: =IF(C28>=1,(K28-C28)*(1+P28*$E$4/100)/$E$4+Q28+S28,"") | F28: =IF(C28>=1,(K28-C28)*(1+$P28*$F$4/100)/$F$4+Q28+S28, "") | G28: =IF(C28>=1, (K28-C28)*(1+$P28*$G$4/100)/$G$4+Q28+S28,"") | H28: =IF(C28>=1, (K28-C28)*(1+$P28*$H$4/100)/$H$4+Q28+S28, "") | I28: =IF(C28>=1, (K28-C28)*(1+$P28*$I$4/100)/$I$4+Q28+S28, "") | K28: =116765 -> 116765 | L28: =110072 -> 110072 | M28: =112303+1200 -> 113503 | N28: =114534+1200 -> 115734 | O28: =116765+1100 -> 117865 | P28: 2.17 | R28: 250 | S28: 125 | U28: 500 | V28: 100 | W28: 07/01/2024 | X28: MB-2024-022
A29: 106900 | B29: RAIDER150 (FU150DY3-MGP BLUE)NEW | D29: =IF(C29>=1,(K29-C29)*(1+P29*$D$4/100)/$D$4+Q29+R29,"") | E29: =IF(C29>=1,(K29-C29)*(1+P29*$E$4/100)/$E$4+Q29+S29,"") | F29: =IF(C29>=1,(K29-C29)*(1+$P29*$F$4/100)/$F$4+Q29+S29, "") | G29: =IF(C29>=1, (K29-C29)*(1+$P29*$G$4/100)/$G$4+Q29+S29,"") | H29: =IF(C29>=1, (K29-C29)*(1+$P29*$H$4/100)/$H$4+Q29+S29, "") | I29: =IF(C29>=1, (K29-C29)*(1+$P29*$I$4/100)/$I$4+Q29+S29, "") | K29: =114765 -> 114765 | L29: =108072 -> 108072 | M29: =110303+1200 -> 111503 | N29: =112534+1200 -> 113734 | O29: =114765+1100 -> 115865 | P29: 2.17 | R29: 250 | S29: 125 | U29: 500 | V29: 100 | W29: 10/31/2023 | X29: MB-2023-109
A30: 146400 | B30: RAIDER R150 PRO (FU150RL-9)NEW | C30: 50000 | D30: =IF(C30>=1,(K30-C30)*(1+P30*$D$4/100)/$D$4+Q30+R30,"") -> 19187.631 | E30: =IF(C30>=1,(K30-C30)*(1+P30*$E$4/100)/$E$4+Q30+S30,"") -> 10684.631 | F30: =IF(C30>=1,(K30-C30)*(1+$P30*$F$4/100)/$F$4+Q30+S30, "") -> 7891.9645 | G30: =IF(C30>=1, (K30-C30)*(1+$P30*$G$4/100)/$G$4+Q30+S30,"") -> 6495.6312 | H30: =IF(C30>=1, (K30-C30)*(1+$P30*$H$4/100)/$H$4+Q30+S30, "") -> 5657.8312 | I30: =IF(C30>=1, (K30-C30)*(1+$P30*$I$4/100)/$I$4+Q30+S30, "") -> 5099.2979 | K30: =150536 -> 150536 | L30: 146400 | M30: =147779+1200 -> 148979 | N30: =149157+1200 -> 150357 | O30: =150536+1100 -> 151636 | P30: 2.17 | R30: 250 | S30: 125 | U30: 500 | V30: 100 | W30: 10/13/2025 | X30: MB-2025-048
A31: 130000 | B31: RAIDER R150 BLADE EDITION (FU150RF-9)NEW | C31: 50000 | D31: =IF(C31>=1,(K31-C31)*(1+P31*$D$4/100)/$D$4+Q31+R31,"") -> 16175.083 | E31: =IF(C31>=1,(K31-C31)*(1+P31*$E$4/100)/$E$4+Q31+S31,"") -> 9004.8331 | F31: =IF(C31>=1,(K31-C31)*(1+$P31*$F$4/100)/$F$4+Q31+S31, "") -> 6656.4164 | G31: =IF(C31>=1, (K31-C31)*(1+$P31*$G$4/100)/$G$4+Q31+S31,"") -> 5482.2081 | H31: =IF(C31>=1, (K31-C31)*(1+$P31*$H$4/100)/$H$4+Q31+S31, "") -> 4777.6831 | I31: =IF(C31>=1, (K31-C31)*(1+$P31*$I$4/100)/$I$4+Q31+S31, "") -> 4307.9998 | K31: =134543 -> 134543 | L31: 130000 | M31: =131514+1200 -> 132714 | N31: =133029+1200 -> 134229 | O31: =134543+1100 -> 135643 | P31: 2.17 | R31: 250 | S31: 125 | U31: 500 | V31: 100 | W31: 10/13/2025 | X31: MB-2025-047
A32: 97900 | B32: RAIDER150 (FU150DX3-MBLK/MGRY)COMBAT | D32: =IF(C32>=1,(K32-C32)*(1+P32*$D$4/100)/$D$4+Q32+R32,"") | E32: =IF(C32>=1,(K32-C32)*(1+P32*$E$4/100)/$E$4+Q32+S32,"") | F32: =IF(C32>=1,(K32-C32)*(1+$P32*$F$4/100)/$F$4+Q32+S32, "") | G32: =IF(C32>=1, (K32-C32)*(1+$P32*$G$4/100)/$G$4+Q32+S32,"") | H32: =IF(C32>=1, (K32-C32)*(1+$P32*$H$4/100)/$H$4+Q32+S32, "") | I32: =IF(C32>=1, (K32-C32)*(1+$P32*$I$4/100)/$I$4+Q32+S32, "") | K32: 105173 | L32: 98480 | M32: =100711+1200 -> 101911 | N32: =102942+1200 -> 104142 | O32: =105173+1100 -> 106273 | P32: 2.17 | R32: 250 | S32: 125 | U32: 500 | V32: 100 | W32: 43890 | X32: MKTG20-01
A33: 60900 | B33: RAIDERJ110 (Mags) | D33: =IF(C33>=1,(K33-C33)*(1+P33*$D$4/100)/$D$4+Q33+R33,"") | E33: =IF(C33>=1,(K33-C33)*(1+P33*$E$4/100)/$E$4+Q33+S33,"") | F33: =IF(C33>=1,(K33-C33)*(1+$P33*$F$4/100)/$F$4+Q33+S33, "") | G33: =IF(C33>=1, (K33-C33)*(1+$P33*$G$4/100)/$G$4+Q33+S33,"") | H33: =IF(C33>=1, (K33-C33)*(1+$P33*$H$4/100)/$H$4+Q33+S33, "") | I33: =IF(C33>=1, (K33-C33)*(1+$P33*$I$4/100)/$I$4+Q33+S33, "") | K33: 65795 | L33: 62600 | M33: =64565+60+240 -> 64865 | N33: =65630+60+240 -> 65930 | O33: =66595+60+240 -> 66895 | P33: 3 | R33: 250 | S33: 125 | U33: 800 | V33: 100
A34: 64900 | B34: RAIDERJ115LB FI (Spoke) | D34: =IF(C34>=1,(K34-C34)*(1+P34*$D$4/100)/$D$4+Q34+R34,"") | E34: =IF(C34>=1,(K34-C34)*(1+P34*$E$4/100)/$E$4+Q34+S34,"") | F34: =IF(C34>=1,(K34-C34)*(1+$P34*$F$4/100)/$F$4+Q34+S34, "") | G34: =IF(C34>=1, (K34-C34)*(1+$P34*$G$4/100)/$G$4+Q34+S34,"") | H34: =IF(C34>=1, (K34-C34)*(1+$P34*$H$4/100)/$H$4+Q34+S34, "") | I34: =IF(C34>=1, (K34-C34)*(1+$P34*$I$4/100)/$I$4+Q34+S34, "") | K34: 68163 | L34: 66587 | M34: =68072+240 -> 68312 | N34: =68597+240 -> 68837 | O34: =69023+240 -> 69263 | P34: 3 | R34: 250 | S34: 125 | U34: 700 | V34: 100
A35: 69900 | B35: RAIDERJ115LE FI (MAGS) | D35: =IF(C35>=1,(K35-C35)*(1+P35*$D$4/100)/$D$4+Q35+R35,"") | E35: =IF(C35>=1,(K35-C35)*(1+P35*$E$4/100)/$E$4+Q35+S35,"") | F35: =IF(C35>=1,(K35-C35)*(1+$P35*$F$4/100)/$F$4+Q35+S35, "") | G35: =IF(C35>=1, (K35-C35)*(1+$P35*$G$4/100)/$G$4+Q35+S35,"") | H35: =IF(C35>=1, (K35-C35)*(1+$P35*$H$4/100)/$H$4+Q35+S35, "") | I35: =IF(C35>=1, (K35-C35)*(1+$P35*$I$4/100)/$I$4+Q35+S35, "") | K35: 72655 | L35: 71302 | M35: =71753+1200 -> 72953 | N35: =72204+1200 -> 73404 | O35: =72655+1100 -> 73755 | P35: 3 | R35: 250 | S35: 125 | U35: 700 | V35: 100
A36: 64900 | B36: RAIDERJ115LX ABLUE (Spokes)NEW | D36: =IF(C36>=1,(K36-C36)*(1+P36*$D$4/100)/$D$4+Q36+R36,"") | E36: =IF(C36>=1,(K36-C36)*(1+P36*$E$4/100)/$E$4+Q36+S36,"") | F36: =IF(C36>=1,(K36-C36)*(1+$P36*$F$4/100)/$F$4+Q36+S36, "") | G36: =IF(C36>=1, (K36-C36)*(1+$P36*$G$4/100)/$G$4+Q36+S36,"") | H36: =IF(C36>=1, (K36-C36)*(1+$P36*$H$4/100)/$H$4+Q36+S36, "") | I36: =IF(C36>=1, (K36-C36)*(1+$P36*$I$4/100)/$I$4+Q36+S36, "") | K36: 68163 | L36: 66587 | M36: =68072+240 -> 68312 | N36: =68597+240 -> 68837 | O36: =69023+240 -> 69263 | P36: 3 | R36: 250 | S36: 125 | U36: 700 | V36: 100
A37: 70900 | B37: RAIDERJ115LE MBLACK (Mags) NEW | D37: =IF(C37>=1,(K37-C37)*(1+P37*$D$4/100)/$D$4+Q37+R37,"") | E37: =IF(C37>=1,(K37-C37)*(1+P37*$E$4/100)/$E$4+Q37+S37,"") | F37: =IF(C37>=1,(K37-C37)*(1+$P37*$F$4/100)/$F$4+Q37+S37, "") | G37: =IF(C37>=1, (K37-C37)*(1+$P37*$G$4/100)/$G$4+Q37+S37,"") | H37: =IF(C37>=1, (K37-C37)*(1+$P37*$H$4/100)/$H$4+Q37+S37, "") | I37: =IF(C37>=1, (K37-C37)*(1+$P37*$I$4/100)/$I$4+Q37+S37, "") | K37: 73655 | L37: 72302 | M37: =72753+1200 -> 73953 | N37: =73204+1200 -> 74404 | O37: =73655+1100 -> 74755 | P37: 2.5 | R37: 250 | S37: 125 | U37: 600 | V37: 100
A38: 65900 | B38: RAIDERJ115LX MBLACK (Spokes)NEW | D38: =IF(C38>=1,(K38-C38)*(1+P38*$D$4/100)/$D$4+Q38+R38,"") | E38: =IF(C38>=1,(K38-C38)*(1+P38*$E$4/100)/$E$4+Q38+S38,"") | F38: =IF(C38>=1,(K38-C38)*(1+$P38*$F$4/100)/$F$4+Q38+S38, "") | G38: =IF(C38>=1, (K38-C38)*(1+$P38*$G$4/100)/$G$4+Q38+S38,"") | H38: =IF(C38>=1, (K38-C38)*(1+$P38*$H$4/100)/$H$4+Q38+S38, "") | I38: =IF(C38>=1, (K38-C38)*(1+$P38*$I$4/100)/$I$4+Q38+S38, "") | K38: 69481 | L38: 68157 | M38: =68598+1200 -> 69798 | N38: =69039+1200 -> 70239 | O38: =69481+1100 -> 70581 | P38: 2.5 | R38: 250 | S38: 125 | U38: 600 | V38: 100
A39: 67900 | B39: RAIDERJ115LX MOTO GP (Mags) NEW | D39: =IF(C39>=1,(K39-C39)*(1+P39*$D$4/100)/$D$4+Q39+R39,"") | E39: =IF(C39>=1,(K39-C39)*(1+P39*$E$4/100)/$E$4+Q39+S39,"") | F39: =IF(C39>=1,(K39-C39)*(1+$P39*$F$4/100)/$F$4+Q39+S39, "") | G39: =IF(C39>=1, (K39-C39)*(1+$P39*$G$4/100)/$G$4+Q39+S39,"") | H39: =IF(C39>=1, (K39-C39)*(1+$P39*$H$4/100)/$H$4+Q39+S39, "") | I39: =IF(C39>=1, (K39-C39)*(1+$P39*$I$4/100)/$I$4+Q39+S39, "") | K39: 71423 | L39: 70063 | M39: =70516+1200 -> 71716 | N39: =70969+1200 -> 72169 | O39: =71423+1100 -> 72523 | P39: 3 | R39: 250 | S39: 125 | U39: 700 | V39: 100
A40: 70900 | B40: RAIDER J CROSSOVER(FJ110LB2) | D40: =IF(C40>=1,(K40-C40)*(1+P40*$D$4/100)/$D$4+Q40+R40,"") | E40: =IF(C40>=1,(K40-C40)*(1+P40*$E$4/100)/$E$4+Q40+S40,"") | F40: =IF(C40>=1,(K40-C40)*(1+$P40*$F$4/100)/$F$4+Q40+S40, "") | G40: =IF(C40>=1, (K40-C40)*(1+$P40*$G$4/100)/$G$4+Q40+S40,"") | H40: =IF(C40>=1, (K40-C40)*(1+$P40*$H$4/100)/$H$4+Q40+S40, "") | I40: =IF(C40>=1, (K40-C40)*(1+$P40*$I$4/100)/$I$4+Q40+S40, "") | K40: =74655 -> 74655 | L40: =73179 -> 73179 | M40: =73671+1200 -> 74871 | N40: =74163+1200 -> 75363 | O40: =74655+1100 -> 75755 | P40: 2.5 | R40: 250 | S40: 125 | U40: 600 | V40: 100 | W40: 07/01/2024 | X40: MB-2024-021
A41: 63900 | B41: SHOOTER FI (Mags/FV110LE) | D41: =IF(C41>=1,(K41-C41)*(1+P41*$D$4/100)/$D$4+Q41+R41,"") | E41: =IF(C41>=1,(K41-C41)*(1+P41*$E$4/100)/$E$4+Q41+S41,"") | F41: =IF(C41>=1,(K41-C41)*(1+$P41*$F$4/100)/$F$4+Q41+S41, "") | G41: =IF(C41>=1, (K41-C41)*(1+$P41*$G$4/100)/$G$4+Q41+S41,"") | H41: =IF(C41>=1, (K41-C41)*(1+$P41*$H$4/100)/$H$4+Q41+S41, "") | I41: =IF(C41>=1, (K41-C41)*(1+$P41*$I$4/100)/$I$4+Q41+S41, "") | K41: 68095 | L41: 65938 | M41: =67617+240 -> 67857 | N41: =68336+240 -> 68576 | O41: =68955+240 -> 69195 | P41: 2.17 | R41: 250 | S41: 125 | U41: 200 | V41: 50
...

Sheet FOR PRINT
A2: SMDI
A3: UPDATE: OCTBER 13, 2025 11:30 AM BY: I.T. DEPT.
A4: D.Price | B4: BRAND/MODEL | C4: DP | D4: 6 | E4: 12 | F4: 18 | G4: 24 | H4: 30 | I4: 36 | K4: LCP | L4: COD | M4: 30 Days | N4: 60 Days | O4: 90 Days | P4: I.R. ( + ) | R4: 6 | S4: 12-36 | U4: Rebate | W4: DATE | X4: MB
C5: BELOW
A6: SUZUKI
A7: 84900 | B7: ACCESS 125 (UZ125NEY) | C7: 20000 | D7: =IF(C7>=1,(K7-C7)*(1+P7*$D$4/100)/$D$4+Q7+R7,"") -> 12975.487 | E7: =IF(C7>=1,(K7-C7)*(1+P7*$E$4/100)/$E$4+Q7+S7,"") -> 7220.7369 | F7: =IF(C7>=1,(K7-C7)*(1+$P7*$F$4/100)/$F$4+Q7+S7, "") -> 5344.1536 | G7: =IF(C7>=1, (K7-C7)*(1+$P7*$G$4/100)/$G$4+Q7+S7,"") -> 4405.8619 | H7: =IF(C7>=1, (K7-C7)*(1+$P7*$H$4/100)/$H$4+Q7+S7, "") -> 3842.8869 | I7: =IF(C7>=1, (K7-C7)*(1+$P7*$I$4/100)/$I$4+Q7+S7, "") -> 3467.5702 | K7: 87557 | L7: 86454 | M7: =86822+1200 -> 88022 | N7: =87189+1200 -> 88389 | O7: =87557+1100 -> 88657 | P7: 2.17 | R7: 250 | S7: 125 | U7: 200 | V7: 100 | W7: 45918 | X7: MB-2025-042
A8: 93900 | B8: ACCESS 125 RIDE CONNECT EDITION (UZ125NES) | C8: 20000 | D8: =IF(C8>=1,(K8-C8)*(1+P8*$D$4/100)/$D$4+Q8+R8,"") -> 14721.646 | E8: =IF(C8>=1,(K8-C8)*(1+P8*$E$4/100)/$E$4+Q8+S8,"") -> 8194.3959 | F8: =IF(C8>=1,(K8-C8)*(1+$P8*$F$4/100)/$F$4+Q8+S8, "") -> 6060.3126 | G8: =IF(C8>=1, (K8-C8)*(1+$P8*$G$4/100)/$G$4+Q8+S8,"") -> 4993.2709 | H8: =IF(C8>=1, (K8-C8)*(1+$P8*$H$4/100)/$H$4+Q8+S8, "") -> 4353.0459 | I8: =IF(C8>=1, (K8-C8)*(1+$P8*$I$4/100)/$I$4+Q8+S8, "") -> 3926.2292 | K8: =96827 -> 96827 | L8: =95419 -> 95419 | M8: =95888+1200 -> 97088 | N8: =96358+1200 -> 97558 | O8: =96827+1100 -> 97927 | P8: 2.17 | R8: 250 | S8: 125 | U8: 200 | V8: 100 | W8: 45918 | X8: MB-2025-043
A9: 66900 | B9: ADDRESS (UK110NE/NZ/NX) | D9: =IF(C9>=1,(K9-C9)*(1+P9*$D$4/100)/$D$4+Q9+R9,"") | E9: =IF(C9>=1,(K9-C9)*(1+P9*$E$4/100)/$E$4+Q9+S9,"") | F9: =IF(C9>=1,(K9-C9)*(1+$P9*$F$4/100)/$F$4+Q9+S9, "") | G9: =IF(C9>=1, (K9-C9)*(1+$P9*$G$4/100)/$G$4+Q9+S9,"") | H9: =IF(C9>=1, (K9-C9)*(1+$P9*$H$4/100)/$H$4+Q9+S9, "") | I9: =IF(C9>=1, (K9-C9)*(1+$P9*$I$4/100)/$I$4+Q9+S9, "") | K9: 70694 | L9: 68026 | M9: =69875+240 -> 70115 | N9: =70764+240 -> 71004 | O9: =71554+240 -> 71794 | P9: 2.17 | R9: 250 | S9: 125 | U9: 200 | V9: 100
A10: 80400 | B10: AVENIS (UN125NE) | D10: =IF(C10>=1,(K10-C10)*(1+P10*$D$4/100)/$D$4+Q10+R10,"") | E10: =IF(C10>=1,(K10-C10)*(1+P10*$E$4/100)/$E$4+Q10+S10,"") | F10: =IF(C10>=1,(K10-C10)*(1+$P10*$F$4/100)/$F$4+Q10+S10, "") | G10: =IF(C10>=1, (K10-C10)*(1+$P10*$G$4/100)/$G$4+Q10+S10,"") | H10: =IF(C10>=1, (K10-C10)*(1+$P10*$H$4/100)/$H$4+Q10+S10, "") | I10: =IF(C10>=1, (K10-C10)*(1+$P10*$I$4/100)/$I$4+Q10+S10, "") | K10: =84878 -> 84878 | L10: =81499 -> 81499 | M10: =82625+1200 -> 83825 | N10: =83751+1200 -> 84951 | O10: =84878+1100 -> 85978 | P10: 2.17 | R10: 250 | S10: 125 | U10: 200 | V10: 100 | W10: 10/31/2023 | X10: MB-2023-113
A11: 83400 | B11: BURGMAN STREET (UB125 NMB / NMX / NM-9) | D11: =IF(C11>=1,(K11-C11)*(1+P11*$D$4/100)/$D$4+Q11+R11,"") | E11: =IF(C11>=1,(K11-C11)*(1+P11*$E$4/100)/$E$4+Q11+S11,"") | F11: =IF(C11>=1,(K11-C11)*(1+$P11*$F$4/100)/$F$4+Q11+S11, "") | G11: =IF(C11>=1, (K11-C11)*(1+$P11*$G$4/100)/$G$4+Q11+S11,"") | H11: =IF(C11>=1, (K11-C11)*(1+$P11*$H$4/100)/$H$4+Q11+S11, "") | I11: =IF(C11>=1, (K11-C11)*(1+$P11*$I$4/100)/$I$4+Q11+S11, "") | K11: =87306 -> 87306 | L11: =84432 -> 84432 | M11: =85390+1200 -> 86590 | N11: =86348+1200 -> 87548 | O11: =87306+1100 -> 88406 | P11: 2.17 | R11: 250 | S11: 125 | U11: 200 | V11: 100 | W11: 10/31/2023 | X11: MB-2023-114
A12: 92400 | B12: BURGMAN STREET 125 EX (UB125LNM) | D12: =IF(C12>=1,(K12-C12)*(1+P12*$D$4/100)/$D$4+Q12+R12,"") | E12: =IF(C12>=1,(K12-C12)*(1+P12*$E$4/100)/$E$4+Q12+S12,"") | F12: =IF(C12>=1,(K12-C12)*(1+$P12*$F$4/100)/$F$4+Q12+S12, "") | G12: =IF(C12>=1, (K12-C12)*(1+$P12*$G$4/100)/$G$4+Q12+S12,"") | H12: =IF(C12>=1, (K12-C12)*(1+$P12*$H$4/100)/$H$4+Q12+S12, "") | I12: =IF(C12>=1, (K12-C12)*(1+$P12*$I$4/100)/$I$4+Q12+S12, "") | K12: =95262 -> 95262 | L12: =92400 -> 92400 | M12: =93354+1200 -> 94554 | N12: =94308+1200 -> 95508 | O12: =95262+1100 -> 96362 | P12: 2.17 | R12: 250 | S12: 125 | U12: 200 | V12: 100 | W12: 04/14/2023 | X12: MB-2023-078
A13: 48900 | B13: GD110 | D13: =IF(C13>=1,(K13-C13)*(1+P13*$D$4/100)/$D$4+Q13+R13,"") | E13: =IF(C13>=1,(K13-C13)*(1+P13*$E$4/100)/$E$4+Q13+S13,"") | F13: =IF(C13>=1,(K13-C13)*(1+$P13*$F$4/100)/$F$4+Q13+S13, "") | G13: =IF(C13>=1, (K13-C13)*(1+$P13*$G$4/100)/$G$4+Q13+S13,"") | H13: =IF(C13>=1, (K13-C13)*(1+$P13*$H$4/100)/$H$4+Q13+S13, "") | I13: =IF(C13>=1, (K13-C13)*(1+$P13*$I$4/100)/$I$4+Q13+S13, "") | K13: 52555 | L13: 51573 | M13: =52800+60+240 -> 53100 | N13: =53127+60+240 -> 53427 | O13: =53355+60+240 -> 53655 | P13: 3 | R13: 250 | S13: 125 | U13: 500 | V13: 50
A14: 91900 | B14: GIXXER (GSX150RZA_fi) | D14: =IF(C14>=1,(K14-C14)*(1+P14*$D$4/100)/$D$4+Q14+R14,"") | E14: =IF(C14>=1,(K14-C14)*(1+P14*$E$4/100)/$E$4+Q14+S14,"") | F14: =IF(C14>=1,(K14-C14)*(1+$P14*$F$4/100)/$F$4+Q14+S14, "") | G14: =IF(C14>=1, (K14-C14)*(1+$P14*$G$4/100)/$G$4+Q14+S14,"") | H14: =IF(C14>=1, (K14-C14)*(1+$P14*$H$4/100)/$H$4+Q14+S14, "") | I14: =IF(C14>=1, (K14-C14)*(1+$P14*$I$4/100)/$I$4+Q14+S14, "") | K14: 94597 | L14: 92795 | M14: =93395+1200 -> 94595 | N14: =93996+1200 -> 95196 | O14: =94597+1100 -> 95697 | P14: 2.17 | R14: 250 | S14: 125 | U14: 200 | V14: 100
A15: 93900 | B15: GIXXER (GSX150RF ) | D15: =IF(C15>=1,(K15-C15)*(1+P15*$D$4/100)/$D$4+Q15+R15,"") | E15: =IF(C15>=1,(K15-C15)*(1+P15*$E$4/100)/$E$4+Q15+S15,"") | F15: =IF(C15>=1,(K15-C15)*(1+$P15*$F$4/100)/$F$4+Q15+S15, "") | G15: =IF(C15>=1, (K15-C15)*(1+$P15*$G$4/100)/$G$4+Q15+S15,"") | H15: =IF(C15>=1, (K15-C15)*(1+$P15*$H$4/100)/$H$4+Q15+S15, "") | I15: =IF(C15>=1, (K15-C15)*(1+$P15*$I$4/100)/$I$4+Q15+S15, "") | K15: 96597 | L15: 94795 | M15: =95395+1200 -> 96595 | N15: =95996+1200 -> 97196 | O15: =96597+1100 -> 97697 | P15: 2.17 | R15: 250 | S15: 125 | U15: 200 | V15: 100 | W15: 08/29/20 | X15: 2020-31
A16: 104900 | B16: GIXXER 150FI (GSX150RFZ / RF-6 / RF-8 ) 50% | D16: =IF(C16>=1,(K16-C16)*(1+P16*$D$4/100)/$D$4+Q16+R16,"") | E16: =IF(C16>=1,(K16-C16)*(1+P16*$E$4/100)/$E$4+Q16+S16,"") | F16: =IF(C16>=1,(K16-C16)*(1+$P16*$F$4/100)/$F$4+Q16+S16, "") | G16: =IF(C16>=1, (K16-C16)*(1+$P16*$G$4/100)/$G$4+Q16+S16,"") | H16: =IF(C16>=1, (K16-C16)*(1+$P16*$H$4/100)/$H$4+Q16+S16, "") | I16: =IF(C16>=1, (K16-C16)*(1+$P16*$I$4/100)/$I$4+Q16+S16, "") | K16: =108689 -> 108689 | L16: =106887 -> 106887 | M16: =107487+1200 -> 108687 | N16: =108088+1200 -> 109288 | O16: =108689+1100 -> 109789 | P16: 2.17 | R16: 250 | S16: 125 | U16: 200 | V16: 100 | W16: 10/31/2024 | X16: MB-MKTG2024-31
A17: 114900 | B17: GIXXER SF155 SPORTS FULL-FAIRED (GSX150FRFX-8/FRF-8) 50% | D17: =IF(C17>=1,(K17-C17)*(1+P17*$D$4/100)/$D$4+Q17+R17,"") | E17: =IF(C17>=1,(K17-C17)*(1+P17*$E$4/100)/$E$4+Q17+S17,"") | F17: =IF(C17>=1,(K17-C17)*(1+$P17*$F$4/100)/$F$4+Q17+S17, "") | G17: =IF(C17>=1, (K17-C17)*(1+$P17*$G$4/100)/$G$4+Q17+S17,"") | H17: =IF(C17>=1, (K17-C17)*(1+$P17*$H$4/100)/$H$4+Q17+S17, "") | I17: =IF(C17>=1, (K17-C17)*(1+$P17*$I$4/100)/$I$4+Q17+S17, "") | K17: 116878 | L17: =114900 -> 114900 | M17: =115560+1200 -> 116760 | N17: =116219+1200 -> 117419 | O17: =116878+1100 -> 117978 | P17: 2.17 | R17: 250 | S17: 125 | U17: 200 | V17: 100 | W17: 10/31/2024 | X17: MB-2024-030
A18: 192900 | B18: GIXXER SF250 (GSX250FRLX/FRLZ ) NEW 50% | D18: =IF(C18>=1,(K18-C18)*(1+P18*$D$4/100)/$D$4+Q18+R18,"") | E18: =IF(C18>=1,(K18-C18)*(1+P18*$E$4/100)/$E$4+Q18+S18,"") | F18: =IF(C18>=1,(K18-C18)*(1+$P18*$F$4/100)/$F$4+Q18+S18, "") | G18: =IF(C18>=1, (K18-C18)*(1+$P18*$G$4/100)/$G$4+Q18+S18,"") | H18: =IF(C18>=1, (K18-C18)*(1+$P18*$H$4/100)/$H$4+Q18+S18, "") | I18: =IF(C18>=1, (K18-C18)*(1+$P18*$I$4/100)/$I$4+Q18+S18, "") | K18: =200824 -> 200824 | L18: 193492 | M18: =195936+1200 -> 197136 | N18: =198380+1200 -> 199580 | O18: =200824+1100 -> 201924 | P18: 2.17 | R18: 250 | S18: 125 | U18: 500 | V18: 100 | W18: 10/31/2023 | X18: MB-2023-116
A19: 182900 | B19: GIXXER250 (GSX250RL / RL-6) NEW 50% | D19: =IF(C19>=1,(K19-C19)*(1+P19*$D$4/100)/$D$4+Q19+R19,"") | E19: =IF(C19>=1,(K19-C19)*(1+P19*$E$4/100)/$E$4+Q19+S19,"") | F19: =IF(C19>=1,(K19-C19)*(1+$P19*$F$4/100)/$F$4+Q19+S19, "") | G19: =IF(C19>=1, (K19-C19)*(1+$P19*$G$4/100)/$G$4+Q19+S19,"") | H19: =IF(C19>=1, (K19-C19)*(1+$P19*$H$4/100)/$H$4+Q19+S19, "") | I19: =IF(C19>=1, (K19-C19)*(1+$P19*$I$4/100)/$I$4+Q19+S19, "") | K19: =189492 -> 189492 | L19: =183492 -> 183492 | M19: =185425+1200 -> 186625 | N19: =187358+1200 -> 188558 | O19: =189292+1100 -> 190392 | P19: 2.17 | R19: 250 | S19: 125 | U19: 500 | V19: 100 | W19: 10/31/2023 | X19: MB-2023-117
A20: 156000 | B20: GSX - R150 50% DP | D20: =IF(C20>=1,(K20-C20)*(1+P20*$D$4/100)/$D$4+Q20+R20,"") | E20: =IF(C20>=1,(K20-C20)*(1+P20*$E$4/100)/$E$4+Q20+S20,"") | F20: =IF(C20>=1,(K20-C20)*(1+$P20*$F$4/100)/$F$4+Q20+S20, "") | G20: =IF(C20>=1, (K20-C20)*(1+$P20*$G$4/100)/$G$4+Q20+S20,"") | H20: =IF(C20>=1, (K20-C20)*(1+$P20*$H$4/100)/$H$4+Q20+S20, "") | I20: =IF(C20>=1, (K20-C20)*(1+$P20*$I$4/100)/$I$4+Q20+S20, "") | K20: 162285 | L20: 157777 | M20: 160239 | N20: =161742+260 -> 162002 | O20: =163145+260 -> 163405 | P20: 2.5 | R20: 250 | S20: 125 | U20: 300 | V20: 100
A21: 112800 | B21: GSX - S150 50% DP | D21: =IF(C21>=1,(K21-C21)*(1+P21*$D$4/100)/$D$4+Q21+R21,"") | E21: =IF(C21>=1,(K21-C21)*(1+P21*$E$4/100)/$E$4+Q21+S21,"") | F21: =IF(C21>=1,(K21-C21)*(1+$P21*$F$4/100)/$F$4+Q21+S21, "") | G21: =IF(C21>=1, (K21-C21)*(1+$P21*$G$4/100)/$G$4+Q21+S21,"") | H21: =IF(C21>=1, (K21-C21)*(1+$P21*$H$4/100)/$H$4+Q21+S21, "") | I21: =IF(C21>=1, (K21-C21)*(1+$P21*$I$4/100)/$I$4+Q21+S21, "") | K21: 119362 | L21: 116046 | M21: =118111+240 -> 118351 | N21: =119217+240 -> 119457 | O21: =120222+240 -> 120462 | P21: 2.5 | R21: 250 | S21: 125 | U21: 300 | V21: 100
A22: 133900 | B22: GSX - S150MFX 50% DP | D22: =IF(C22>=1,(K22-C22)*(1+P22*$D$4/100)/$D$4+Q22+R22,"") | E22: =IF(C22>=1,(K22-C22)*(1+P22*$E$4/100)/$E$4+Q22+S22,"") | F22: =IF(C22>=1,(K22-C22)*(1+$P22*$F$4/100)/$F$4+Q22+S22, "") | G22: =IF(C22>=1, (K22-C22)*(1+$P22*$G$4/100)/$G$4+Q22+S22,"") | H22: =IF(C22>=1, (K22-C22)*(1+$P22*$H$4/100)/$H$4+Q22+S22, "") | I22: =IF(C22>=1, (K22-C22)*(1+$P22*$I$4/100)/$I$4+Q22+S22, "") | K22: =139045 -> 139045 | L22: =134492 -> 134492 | M22: =136009+1200 -> 137209 | N22: =137527+1200 -> 138727 | O22: =139045+1100 -> 140145 | P22: 2.5 | R22: 250 | S22: 125 | U22: 300 | V22: 100 | W22: 03/01/2023 | X22: MB-2023-066
A23: 93900 | B23: RAIDER150 (FU150SCD2) | D23: =IF(C23>=1,(K23-C23)*(1+P23*$D$4/100)/$D$4+Q23+R23,"") | E23: =IF(C23>=1,(K23-C23)*(1+P23*$E$4/100)/$E$4+Q23+S23,"") | F23: =IF(C23>=1,(K23-C23)*(1+$P23*$F$4/100)/$F$4+Q23+S23, "") | G23: =IF(C23>=1, (K23-C23)*(1+$P23*$G$4/100)/$G$4+Q23+S23,"") | H23: =IF(C23>=1, (K23-C23)*(1+$P23*$H$4/100)/$H$4+Q23+S23, "") | I23: =IF(C23>=1, (K23-C23)*(1+$P23*$I$4/100)/$I$4+Q23+S23, "") | K23: 101703 | L23: 94600 | M23: =96968+1200 -> 98168 | N23: =99336+1200 -> 100536 | O23: =101703+1100 -> 102803 | P23: 3 | R23: 250 | S23: 125 | U23: 500 | V23: 100
A24: 95900 | B24: RAIDER150 (FU150SCD2)RELO&MGP ED. | D24: =IF(C24>=1,(K24-C24)*(1+P24*$D$4/100)/$D$4+Q24+R24,"") | E24: =IF(C24>=1,(K24-C24)*(1+P24*$E$4/100)/$E$4+Q24+S24,"") | F24: =IF(C24>=1,(K24-C24)*(1+$P24*$F$4/100)/$F$4+Q24+S24, "") | G24: =IF(C24>=1, (K24-C24)*(1+$P24*$G$4/100)/$G$4+Q24+S24,"") | H24: =IF(C24>=1, (K24-C24)*(1+$P24*$H$4/100)/$H$4+Q24+S24, "") | I24: =IF(C24>=1, (K24-C24)*(1+$P24*$I$4/100)/$I$4+Q24+S24, "") | K24: 103703 | L24: 93800 | M24: =99928+240 -> 100168 | N24: =102296+240 -> 102536 | O24: =104563+240 -> 104803 | P24: 2.17 | R24: 250 | S24: 125 | U24: 500 | V24: 100
A25: 96900 | B25: RAIDER150 (FU150DX2-MBLACK)NEW | D25: =IF(C25>=1,(K25-C25)*(1+P25*$D$4/100)/$D$4+Q25+R25,"") | E25: =IF(C25>=1,(K25-C25)*(1+P25*$E$4/100)/$E$4+Q25+S25,"") | F25: =IF(C25>=1,(K25-C25)*(1+$P25*$F$4/100)/$F$4+Q25+S25, "") | G25: =IF(C25>=1, (K25-C25)*(1+$P25*$G$4/100)/$G$4+Q25+S25,"") | H25: =IF(C25>=1, (K25-C25)*(1+$P25*$H$4/100)/$H$4+Q25+S25, "") | I25: =IF(C25>=1, (K25-C25)*(1+$P25*$I$4/100)/$I$4+Q25+S25, "") | K25: 104703 | L25: 97600 | M25: =99967+1200 -> 101167 | N25: =102335+1200 -> 103535 | O25: =104703+1100 -> 105803 | P25: 2.17 | R25: 250 | S25: 125 | U25: 500 | V25: 100
A26: 118400 | B26: RAIDER R150_fi (FU150 MFQ/MFJ/MFX/MFZ)50% | D26: =IF(C26>=1,(K26-C26)*(1+P26*$D$4/100)/$D$4+Q26+R26,"") | E26: =IF(C26>=1,(K26-C26)*(1+P26*$E$4/100)/$E$4+Q26+S26,"") | F26: =IF(C26>=1,(K26-C26)*(1+$P26*$F$4/100)/$F$4+Q26+S26, "") | G26: =IF(C26>=1, (K26-C26)*(1+$P26*$G$4/100)/$G$4+Q26+S26,"") | H26: =IF(C26>=1, (K26-C26)*(1+$P26*$H$4/100)/$H$4+Q26+S26, "") | I26: =IF(C26>=1, (K26-C26)*(1+$P26*$I$4/100)/$I$4+Q26+S26, "") | K26: =123210 -> 123210 | L26: =118992 -> 118992 | M26: =120398+1200 -> 121598 | N26: =121804+1200 -> 123004 | O26: =123210+1100 -> 124310 | P26: 2.17 | R26: 250 | S26: 125 | U26: 500 | V26: 100 | W26: 05/31/2023 | X26: MB-2023-091
A27: 121900 | B27: RAIDER R150_fi Rugged & Sport Edition(FU150 MFX-8/MFZ-8/MFS-8) 50% | D27: =IF(C27>=1,(K27-C27)*(1+P27*$D$4/100)/$D$4+Q27+R27,"") | E27: =IF(C27>=1,(K27-C27)*(1+P27*$E$4/100)/$E$4+Q27+S27,"") | F27: =IF(C27>=1,(K27-C27)*(1+$P27*$F$4/100)/$F$4+Q27+S27, "") | G27: =IF(C27>=1, (K27-C27)*(1+$P27*$G$4/100)/$G$4+Q27+S27,"") | H27: =IF(C27>=1, (K27-C27)*(1+$P27*$H$4/100)/$H$4+Q27+S27, "") | I27: =IF(C27>=1, (K27-C27)*(1+$P27*$I$4/100)/$I$4+Q27+S27, "") | K27: =126710 -> 126710 | L27: =122492 -> 122492 | M27: =123898+1200 -> 125098 | N27: =125304+1200 -> 126504 | O27: =126710+1100 -> 127810 | P27: 2.17 | R27: 250 | S27: 125 | U27: 500 | V27: 100 | W27: 07/01/2024 | X27: MB-2024-023
A28: 108900 | B28: RAIDER150 (FU150CD3-7)NEW | D28: =IF(C28>=1,(K28-C28)*(1+P28*$D$4/100)/$D$4+Q28+R28,"") | E28: =IF(C28>=1,(K28-C28)*(1+P28*$E$4/100)/$E$4+Q28+S28,"") | F28: =IF(C28>=1,(K28-C28)*(1+$P28*$F$4/100)/$F$4+Q28+S28, "") | G28: =IF(C28>=1, (K28-C28)*(1+$P28*$G$4/100)/$G$4+Q28+S28,"") | H28: =IF(C28>=1, (K28-C28)*(1+$P28*$H$4/100)/$H$4+Q28+S28, "") | I28: =IF(C28>=1, (K28-C28)*(1+$P28*$I$4/100)/$I$4+Q28+S28, "") | K28: =116765 -> 116765 | L28: =110072 -> 110072 | M28: =112303+1200 -> 113503 | N28: =114534+1200 -> 115734 | O28: =116765+1100 -> 117865 | P28: 2.17 | R28: 250 | S28: 125 | U28: 500 | V28: 100 | W28: 07/01/2024 | X28: MB-2024-022
A29: 106900 | B29: RAIDER150 (FU150DY3-MGP BLUE)NEW | D29: =IF(C29>=1,(K29-C29)*(1+P29*$D$4/100)/$D$4+Q29+R29,"") | E29: =IF(C29>=1,(K29-C29)*(1+P29*$E$4/100)/$E$4+Q29+S29,"") | F29: =IF(C29>=1,(K29-C29)*(1+$P29*$F$4/100)/$F$4+Q29+S29, "") | G29: =IF(C29>=1, (K29-C29)*(1+$P29*$G$4/100)/$G$4+Q29+S29,"") | H29: =IF(C29>=1, (K29-C29)*(1+$P29*$H$4/100)/$H$4+Q29+S29, "") | I29: =IF(C29>=1, (K29-C29)*(1+$P29*$I$4/100)/$I$4+Q29+S29, "") | K29: =114765 -> 114765 | L29: =108072 -> 108072 | M29: =110303+1200 -> 111503 | N29: =112534+1200 -> 113734 | O29: =114765+1100 -> 115865 | P29: 2.17 | R29: 250 | S29: 125 | U29: 500 | V29: 100 | W29: 10/31/2023 | X29: MB-2023-109
A30: 146400 | B30: RAIDER R150 PRO (FU150RL-9)NEW | C30: 50000 | D30: =IF(C30>=1,(K30-C30)*(1+P30*$D$4/100)/$D$4+Q30+R30,"") -> 19187.631 | E30: =IF(C30>=1,(K30-C30)*(1+P30*$E$4/100)/$E$4+Q30+S30,"") -> 10684.631 | F30: =IF(C30>=1,(K30-C30)*(1+$P30*$F$4/100)/$F$4+Q30+S30, "") -> 7891.9645 | G30: =IF(C30>=1, (K30-C30)*(1+$P30*$G$4/100)/$G$4+Q30+S30,"") -> 6495.6312 | H30: =IF(C30>=1, (K30-C30)*(1+$P30*$H$4/100)/$H$4+Q30+S30, "") -> 5657.8312 | I30: =IF(C30>=1, (K30-C30)*(1+$P30*$I$4/100)/$I$4+Q30+S30, "") -> 5099.2979 | K30: =150536 -> 150536 | L30: 146400 | M30: =147779+1200 -> 148979 | N30: =149157+1200 -> 150357 | O30: =150536+1100 -> 151636 | P30: 2.17 | R30: 250 | S30: 125 | U30: 500 | V30: 100 | W30: 10/13/2025 | X30: MB-2025-048
A31: 130000 | B31: RAIDER R150 BLADE EDITION (FU150RF-9)NEW | C31: 50000 | D31: =IF(C31>=1,(K31-C31)*(1+P31*$D$4/100)/$D$4+Q31+R31,"") -> 16175.083 | E31: =IF(C31>=1,(K31-C31)*(1+P31*$E$4/100)/$E$4+Q31+S31,"") -> 9004.8331 | F31: =IF(C31>=1,(K31-C31)*(1+$P31*$F$4/100)/$F$4+Q31+S31, "") -> 6656.4164 | G31: =IF(C31>=1, (K31-C31)*(1+$P31*$G$4/100)/$G$4+Q31+S31,"") -> 5482.2081 | H31: =IF(C31>=1, (K31-C31)*(1+$P31*$H$4/100)/$H$4+Q31+S31, "") -> 4777.6831 | I31: =IF(C31>=1, (K31-C31)*(1+$P31*$I$4/100)/$I$4+Q31+S31, "") -> 4307.9998 | K31: =134543 -> 134543 | L31: 130000 | M31: =131514+1200 -> 132714 | N31: =133029+1200 -> 134229 | O31: =134543+1100 -> 135643 | P31: 2.17 | R31: 250 | S31: 125 | U31: 500 | V31: 100 | W31: 10/13/2025 | X31: MB-2025-047
A32: 97900 | B32: RAIDER150 (FU150DX3-MBLK/MGRY)COMBAT | D32: =IF(C32>=1,(K32-C32)*(1+P32*$D$4/100)/$D$4+Q32+R32,"") | E32: =IF(C32>=1,(K32-C32)*(1+P32*$E$4/100)/$E$4+Q32+S32,"") | F32: =IF(C32>=1,(K32-C32)*(1+$P32*$F$4/100)/$F$4+Q32+S32, "") | G32: =IF(C32>=1, (K32-C32)*(1+$P32*$G$4/100)/$G$4+Q32+S32,"") | H32: =IF(C32>=1, (K32-C32)*(1+$P32*$H$4/100)/$H$4+Q32+S32, "") | I32: =IF(C32>=1, (K32-C32)*(1+$P32*$I$4/100)/$I$4+Q32+S32, "") | K32: 105173 | L32: 98480 | M32: =100711+1200 -> 101911 | N32: =102942+1200 -> 104142 | O32: =105173+1100 -> 106273 | P32: 2.17 | R32: 250 | S32: 125 | U32: 500 | V32: 100 | W32: 43890 | X32: MKTG20-01
A33: 60900 | B33: RAIDERJ110 (Mags) | D33: =IF(C33>=1,(K33-C33)*(1+P33*$D$4/100)/$D$4+Q33+R33,"") | E33: =IF(C33>=1,(K33-C33)*(1+P33*$E$4/100)/$E$4+Q33+S33,"") | F33: =IF(C33>=1,(K33-C33)*(1+$P33*$F$4/100)/$F$4+Q33+S33, "") | G33: =IF(C33>=1, (K33-C33)*(1+$P33*$G$4/100)/$G$4+Q33+S33,"") | H33: =IF(C33>=1, (K33-C33)*(1+$P33*$H$4/100)/$H$4+Q33+S33, "") | I33: =IF(C33>=1, (K33-C33)*(1+$P33*$I$4/100)/$I$4+Q33+S33, "") | K33: 65795 | L33: 62600 | M33: =64565+60+240 -> 64865 | N33: =65630+60+240 -> 65930 | O33: =66595+60+240 -> 66895 | P33: 3 | R33: 250 | S33: 125 | U33: 800 | V33: 100
A34: 64900 | B34: RAIDERJ115LB FI (Spoke) | D34: =IF(C34>=1,(K34-C34)*(1+P34*$D$4/100)/$D$4+Q34+R34,"") | E34: =IF(C34>=1,(K34-C34)*(1+P34*$E$4/100)/$E$4+Q34+S34,"") | F34: =IF(C34>=1,(K34-C34)*(1+$P34*$F$4/100)/$F$4+Q34+S34, "") | G34: =IF(C34>=1, (K34-C34)*(1+$P34*$G$4/100)/$G$4+Q34+S34,"") | H34: =IF(C34>=1, (K34-C34)*(1+$P34*$H$4/100)/$H$4+Q34+S34, "") | I34: =IF(C34>=1, (K34-C34)*(1+$P34*$I$4/100)/$I$4+Q34+S34, "") | K34: 68163 | L34: 66587 | M34: =68072+240 -> 68312 | N34: =68597+240 -> 68837 | O34: =69023+240 -> 69263 | P34: 3 | R34: 250 | S34: 125 | U34: 700 | V34: 100
A35: 69900 | B35: RAIDERJ115LE FI (MAGS) | D35: =IF(C35>=1,(K35-C35)*(1+P35*$D$4/100)/$D$4+Q35+R35,"") | E35: =IF(C35>=1,(K35-C35)*(1+P35*$E$4/100)/$E$4+Q35+S35,"") | F35: =IF(C35>=1,(K35-C35)*(1+$P35*$F$4/100)/$F$4+Q35+S35, "") | G35: =IF(C35>=1, (K35-C35)*(1+$P35*$G$4/100)/$G$4+Q35+S35,"") | H35: =IF(C35>=1, (K35-C35)*(1+$P35*$H$4/100)/$H$4+Q35+S35, "") | I35: =IF(C35>=1, (K35-C35)*(1+$P35*$I$4/100)/$I$4+Q35+S35, "") | K35: 72655 | L35: 71302 | M35: =71753+1200 -> 72953 | N35: =72204+1200 -> 73404 | O35: =72655+1100 -> 73755 | P35: 3 | R35: 250 | S35: 125 | U35: 700 | V35: 100
A36: 64900 | B36: RAIDERJ115LX ABLUE (Spokes)NEW | D36: =IF(C36>=1,(K36-C36)*(1+P36*$D$4/100)/$D$4+Q36+R36,"") | E36: =IF(C36>=1,(K36-C36)*(1+P36*$E$4/100)/$E$4+Q36+S36,"") | F36: =IF(C36>=1,(K36-C36)*(1+$P36*$F$4/100)/$F$4+Q36+S36, "") | G36: =IF(C36>=1, (K36-C36)*(1+$P36*$G$4/100)/$G$4+Q36+S36,"") | H36: =IF(C36>=1, (K36-C36)*(1+$P36*$H$4/100)/$H$4+Q36+S36, "") | I36: =IF(C36>=1, (K36-C36)*(1+$P36*$I$4/100)/$I$4+Q36+S36, "") | K36: 68163 | L36: 66587 | M36: =68072+240 -> 68312 | N36: =68597+240 -> 68837 | O36: =69023+240 -> 69263 | P36: 3 | R36: 250 | S36: 125 | U36: 700 | V36: 100
A37: 70900 | B37: RAIDERJ115LE MBLACK (Mags) NEW | D37: =IF(C37>=1,(K37-C37)*(1+P37*$D$4/100)/$D$4+Q37+R37,"") | E37: =IF(C37>=1,(K37-C37)*(1+P37*$E$4/100)/$E$4+Q37+S37,"") | F37: =IF(C37>=1,(K37-C37)*(1+$P37*$F$4/100)/$F$4+Q37+S37, "") | G37: =IF(C37>=1, (K37-C37)*(1+$P37*$G$4/100)/$G$4+Q37+S37,"") | H37: =IF(C37>=1, (K37-C37)*(1+$P37*$H$4/100)/$H$4+Q37+S37, "") | I37: =IF(C37>=1, (K37-C37)*(1+$P37*$I$4/100)/$I$4+Q37+S37, "") | K37: 73655 | L37: 72302 | M37: =72753+1200 -> 73953 | N37: =73204+1200 -> 74404 | O37: =73655+1100 -> 74755 | P37: 2.5 | R37: 250 | S37: 125 | U37: 600 | V37: 100
A38: 65900 | B38: RAIDERJ115LX MBLACK (Spokes)NEW | D38: =IF(C38>=1,(K38-C38)*(1+P38*$D$4/100)/$D$4+Q38+R38,"") | E38: =IF(C38>=1,(K38-C38)*(1+P38*$E$4/100)/$E$4+Q38+S38,"") | F38: =IF(C38>=1,(K38-C38)*(1+$P38*$F$4/100)/$F$4+Q38+S38, "") | G38: =IF(C38>=1, (K38-C38)*(1+$P38*$G$4/100)/$G$4+Q38+S38,"") | H38: =IF(C38>=1, (K38-C38)*(1+$P38*$H$4/100)/$H$4+Q38+S38, "") | I38: =IF(C38>=1, (K38-C38)*(1+$P38*$I$4/100)/$I$4+Q38+S38, "") | K38: 69481 | L38: 68157 | M38: =68598+1200 -> 69798 | N38: =69039+1200 -> 70239 | O38: =69481+1100 -> 70581 | P38: 2.5 | R38: 250 | S38: 125 | U38: 600 | V38: 100
A39: 67900 | B39: RAIDERJ115LX MOTO GP (Mags) NEW | D39: =IF(C39>=1,(K39-C39)*(1+P39*$D$4/100)/$D$4+Q39+R39,"") | E39: =IF(C39>=1,(K39-C39)*(1+P39*$E$4/100)/$E$4+Q39+S39,"") | F39: =IF(C39>=1,(K39-C39)*(1+$P39*$F$4/100)/$F$4+Q39+S39, "") | G39: =IF(C39>=1, (K39-C39)*(1+$P39*$G$4/100)/$G$4+Q39+S39,"") | H39: =IF(C39>=1, (K39-C39)*(1+$P39*$H$4/100)/$H$4+Q39+S39, "") | I39: =IF(C39>=1, (K39-C39)*(1+$P39*$I$4/100)/$I$4+Q39+S39, "") | K39: 71423 | L39: 70063 | M39: =70516+1200 -> 71716 | N39: =70969+1200 -> 72169 | O39: =71423+1100 -> 72523 | P39: 3 | R39: 250 | S39: 125 | U39: 700 | V39: 100
A40: 70900 | B40: RAIDER J CROSSOVER(FJ110LB2) | D40: =IF(C40>=1,(K40-C40)*(1+P40*$D$4/100)/$D$4+Q40+R40,"") | E40: =IF(C40>=1,(K40-C40)*(1+P40*$E$4/100)/$E$4+Q40+S40,"") | F40: =IF(C40>=1,(K40-C40)*(1+$P40*$F$4/100)/$F$4+Q40+S40, "") | G40: =IF(C40>=1, (K40-C40)*(1+$P40*$G$4/100)/$G$4+Q40+S40,"") | H40: =IF(C40>=1, (K40-C40)*(1+$P40*$H$4/100)/$H$4+Q40+S40, "") | I40: =IF(C40>=1, (K40-C40)*(1+$P40*$I$4/100)/$I$4+Q40+S40, "") | K40: =74655 -> 74655 | L40: =73179 -> 73179 | M40: =73671+1200 -> 74871 | N40: =74163+1200 -> 75363 | O40: =74655+1100 -> 75755 | P40: 2.5 | R40: 250 | S40: 125 | U40: 600 | V40: 100 | W40: 07/01/2024 | X40: MB-2024-021
A41: 63900 | B41: SHOOTER FI (Mags/FV110LE) | D41: =IF(C41>=1,(K41-C41)*(1+P41*$D$4/100)/$D$4+Q41+R41,"") | E41: =IF(C41>=1,(K41-C41)*(1+P41*$E$4/100)/$E$4+Q41+S41,"") | F41: =IF(C41>=1,(K41-C41)*(1+$P41*$F$4/100)/$F$4+Q41+S41, "") | G41: =IF(C41>=1, (K41-C41)*(1+$P41*$G$4/100)/$G$4+Q41+S41,"") | H41: =IF(C41>=1, (K41-C41)*(1+$P41*$H$4/100)/$H$4+Q41+S41, "") | I41: =IF(C41>=1, (K41-C41)*(1+$P41*$I$4/100)/$I$4+Q41+S41, "") | K41: 68095 | L41: 65938 | M41: =67617+240 -> 67857 | N41: =68336+240 -> 68576 | O41: =68955+240 -> 69195 | P41: 2.17 | R41: 250 | S41: 125 | U41: 200 | V41: 50
...

Sheet OLD MODELS
A1: UPDATE: JANUARY 24, 2019 11:00 AM BY: AJF
A2: D.Price | B2: BRAND/MODEL | C2: DP | D2: 6 | E2: 12 | F2: 18 | G2: 24 | H2: 30 | I2: 36 | K2: LCP | L2: COD | M2: 30 Days | N2: 60 Days | O2: 90 Days | P2: I.R. ( + ) | S2: Rebate | U2: DATE
C3: BELOW
A4: SUZUKI
A5: 68900 | B5: AX4 (GA150DAJ) | C5: 1 | D5: =IF(C5>=1,(K5-C5)*(1+P5*PRICING!$D$4/100)/PRICING!$D$4+Q5,"") -> 13554.489 | E5: =IF(C5>=1,(K5-C5)*(1+P5*PRICING!$E$4/100)/PRICING!$E$4+Q5,"") -> 7557.9886 | F5: =IF(C5>=1,(K5-C5)*(1+$P5*PRICING!$F$4/100)/PRICING!$F$4+Q5, "") -> 5559.1553 | G5: =IF(C5>=1, (K5-C5)*(1+$P5*PRICING!$G$4/100)/PRICING!$G$4+Q5,"") -> 4559.7386 | H5: =IF(C5>=1, (K5-C5)*(1+$P5*PRICING!$H$4/100)/PRICING!$H$4+Q5, "") -> 3960.0886 | I5: =IF(C5>=1, (K5-C5)*(1+$P5*PRICING!$I$4/100)/PRICING!$I$4+Q5, "") -> 3560.3219 | K5: 71959 | L5: 69903 | M5: 71548 | N5: 72233 | O5: 72819 | P5: 2.17 | S5: 200 | T5: 100
A6: 89900 | B6: GIXXER (GSX150DEA) | C6: 1 | D6: =IF(C6>=1,(K6-C6)*(1+P6*$D$2/100)/$D$2+Q6,"") -> 17375.695 | E6: =IF(C6>=1,(K6-C6)*(1+P6*$E$2/100)/$E$2+Q6,"") -> 9688.6948 | F6: =IF(C6>=1,(K6-C6)*(1+$P6*$F$2/100)/$F$2+Q6, "") -> 7126.3615 | G6: =IF(C6>=1, (K6-C6)*(1+$P6*$G$2/100)/$G$2+Q6,"") -> 5845.1948 | H6: =IF(C6>=1, (K6-C6)*(1+$P6*$H$2/100)/$H$2+Q6, "") -> 5076.4948 | I6: =IF(C6>=1, (K6-C6)*(1+$P6*$I$2/100)/$I$2+Q6, "") -> 4564.0281 | K6: 92245 | L6: 90488 | M6: 92033 | N6: 92619 | O6: 93105 | P6: 2.17 | S6: 200 | T6: 100
A7: 75900 | B7: HAYATE125 | C7: 1 | D7: =IF(C7>=1,(K7-C7)*(1+P7*$D$2/100)/$D$2+Q7,"") -> 16590.667 | E7: =IF(C7>=1,(K7-C7)*(1+P7*$E$2/100)/$E$2+Q7,"") -> 9377.3333 | F7: =IF(C7>=1,(K7-C7)*(1+$P7*$F$2/100)/$F$2+Q7, "") -> 6972.8889 | G7: =IF(C7>=1, (K7-C7)*(1+$P7*$G$2/100)/$G$2+Q7,"") -> 5770.6667 | H7: =IF(C7>=1, (K7-C7)*(1+$P7*$H$2/100)/$H$2+Q7, "") -> 5049.3333 | I7: =IF(C7>=1, (K7-C7)*(1+$P7*$I$2/100)/$I$2+Q7, "") -> 4568.4444 | K7: 86561 | L7: 82845 | M7: =84984+60 -> 85044 | N7: =86223+60 -> 86283 | O7: =87361+60 -> 87421 | P7: 2.5 | S7: 400 | T7: 100
A8: 63100 | B8: MOLA125 | C8: 1 | D8: =IF(C8>=1,(K8-C8)*(1+P8*$D$2/100)/$D$2+Q8,"") -> 13186.475 | E8: =IF(C8>=1,(K8-C8)*(1+P8*$E$2/100)/$E$2+Q8,"") -> 7453.225 | F8: =IF(C8>=1,(K8-C8)*(1+$P8*$F$2/100)/$F$2+Q8, "") -> 5542.1417 | G8: =IF(C8>=1, (K8-C8)*(1+$P8*$G$2/100)/$G$2+Q8,"") -> 4586.6 | H8: =IF(C8>=1, (K8-C8)*(1+$P8*$H$2/100)/$H$2+Q8, "") -> 4013.275 | I8: =IF(C8>=1, (K8-C8)*(1+$P8*$I$2/100)/$I$2+Q8, "") -> 3631.0583 | K8: 68800 | L8: 66500 | M8: =68167+60 -> 68227 | N8: =68934+60 -> 68994 | O8: =69600+60 -> 69660 | P8: 2.5 | S8: 500 | T8: 100
A9: 61900 | B9: NEX115 | C9: 1 | D9: =IF(C9>=1,(K9-C9)*(1+P9*$D$2/100)/$D$2+Q9,"") -> 12261.54 | E9: =IF(C9>=1,(K9-C9)*(1+P9*$E$2/100)/$E$2+Q9,"") -> 6837.0398 | F9: =IF(C9>=1,(K9-C9)*(1+$P9*$F$2/100)/$F$2+Q9, "") -> 5028.8731 | G9: =IF(C9>=1, (K9-C9)*(1+$P9*$G$2/100)/$G$2+Q9,"") -> 4124.7898 | H9: =IF(C9>=1, (K9-C9)*(1+$P9*$H$2/100)/$H$2+Q9, "") -> 3582.3398 | I9: =IF(C9>=1, (K9-C9)*(1+$P9*$I$2/100)/$I$2+Q9, "") -> 3220.7065 | K9: 65095 | L9: 63897 | M9: =65196+60 -> 65256 | N9: =65595+60 -> 65655 | O9: =65895+60 -> 65955 | P9: 2.17 | S9: 200 | T9: 50
A10: 61900 | B10: RAIDERJ110 (Pro) | C10: 1 | D10: =IF(C10>=1,(K10-C10)*(1+P10*$D$2/100)/$D$2+Q10,"") -> 13116.487 | E10: =IF(C10>=1,(K10-C10)*(1+P10*$E$2/100)/$E$2+Q10,"") -> 7558.6533 | F10: =IF(C10>=1,(K10-C10)*(1+$P10*$F$2/100)/$F$2+Q10, "") -> 5706.0422 | G10: =IF(C10>=1, (K10-C10)*(1+$P10*$G$2/100)/$G$2+Q10,"") -> 4779.7367 | H10: =IF(C10>=1, (K10-C10)*(1+$P10*$H$2/100)/$H$2+Q10, "") -> 4223.9533 | I10: =IF(C10>=1, (K10-C10)*(1+$P10*$I$2/100)/$I$2+Q10, "") -> 3853.4311 | K10: 66695 | L10: 63500 | M10: =65465+60 -> 65525 | N10: =66530+60 -> 66590 | O10: =67495+60 -> 67555 | P10: 3 | S10: 800 | T10: 100
A11: 57900 | B11: RAIDERJ110 (SD) | C11: 1 | D11: =IF(C11>=1,(K11-C11)*(1+P11*PRICING!$D$4/100)/PRICING!$D$4+Q11,"") -> 12329.82 | E11: =IF(C11>=1,(K11-C11)*(1+P11*PRICING!$E$4/100)/PRICING!$E$4+Q11,"") -> 7105.32 | F11: =IF(C11>=1,(K11-C11)*(1+$P11*PRICING!$F$4/100)/PRICING!$F$4+Q11, "") -> 5363.82 | G11: =IF(C11>=1, (K11-C11)*(1+$P11*PRICING!$G$4/100)/PRICING!$G$4+Q11,"") -> 4493.07 | H11: =IF(C11>=1, (K11-C11)*(1+$P11*PRICING!$H$4/100)/PRICING!$H$4+Q11, "") -> 3970.62 | I11: =IF(C11>=1, (K11-C11)*(1+$P11*PRICING!$I$4/100)/PRICING!$I$4+Q11, "") -> 3622.32 | K11: 62695 | L11: 59500 | M11: =61465+60 -> 61525 | N11: =62530+60 -> 62590 | O11: =63495+60 -> 63555 | P11: 3 | S11: 300 | T11: 100
A12: 68900 | B12: SHOGUN PRO (FL125) | C12: 1 | D12: =IF(C12>=1,(K12-C12)*(1+P12*$D$2/100)/$D$2+Q12,"") -> 14223.71 | E12: =IF(C12>=1,(K12-C12)*(1+P12*$E$2/100)/$E$2+Q12,"") -> 8019.6266 | F12: =IF(C12>=1,(K12-C12)*(1+$P12*$F$2/100)/$F$2+Q12, "") -> 5951.5989 | G12: =IF(C12>=1, (K12-C12)*(1+$P12*$G$2/100)/$G$2+Q12,"") -> 4917.585 | H12: =IF(C12>=1, (K12-C12)*(1+$P12*$H$2/100)/$H$2+Q12, "") -> 4297.1766 | I12: =IF(C12>=1, (K12-C12)*(1+$P12*$I$2/100)/$I$2+Q12, "") -> 3883.5711 | K12: 74450 | L12: 71350 | M12: =73284+60 -> 73344 | N12: =74318+60 -> 74378 | O12: =75250+60 -> 75310 | P12: 2.17 | Q12: 200 | S12: 300 | T12: 50
A13: 60900 | B13: SMASH115 (Mags) | C13: 1 | D13: =IF(C13>=1,(K13-C13)*(1+P13*$D$2/100)/$D$2+Q13,"") -> 12676.35 | E13: =IF(C13>=1,(K13-C13)*(1+P13*$E$2/100)/$E$2+Q13,"") -> 7251.85 | F13: =IF(C13>=1,(K13-C13)*(1+$P13*$F$2/100)/$F$2+Q13, "") -> 5443.6833 | G13: =IF(C13>=1, (K13-C13)*(1+$P13*$G$2/100)/$G$2+Q13,"") -> 4539.6 | H13: =IF(C13>=1, (K13-C13)*(1+$P13*$H$2/100)/$H$2+Q13, "") -> 3997.15 | I13: =IF(C13>=1, (K13-C13)*(1+$P13*$I$2/100)/$I$2+Q13, "") -> 3635.5167 | K13: 65095 | L13: 62938 | M13: =64557+60 -> 64617 | N13: =65276+60 -> 65336 | O13: =65895+60 -> 65955 | P13: 2.5 | Q13: 200 | S13: 700 | T13: 100
A14: 67900 | B14: THUNDER125 | C14: 1 | D14: =IF(C14>=1,(K14-C14)*(1+P14*$D$2/100)/$D$2+Q14,"") -> 13320.642 | E14: =IF(C14>=1,(K14-C14)*(1+P14*$E$2/100)/$E$2+Q14,"") -> 7529.0583 | F14: =IF(C14>=1,(K14-C14)*(1+$P14*$F$2/100)/$F$2+Q14, "") -> 5598.5306 | G14: =IF(C14>=1, (K14-C14)*(1+$P14*$G$2/100)/$G$2+Q14,"") -> 4633.2667 | H14: =IF(C14>=1, (K14-C14)*(1+$P14*$H$2/100)/$H$2+Q14, "") -> 4054.1083 | I14: =IF(C14>=1, (K14-C14)*(1+$P14*$I$2/100)/$I$2+Q14, "") -> 3668.0028 | K14: 69500 | L14: 69500 | M14: =70400+60 -> 70460 | N14: =70400+60 -> 70460 | O14: =70300+60 -> 70360 | P14: 2.5 | S14: 350 | T14: 50
A15: 82900 | B15: HAYATE125 FI | C15: 1 | D15: =IF(C15>=1,(K15-C15)*(1+P15*PRICING!$D$4/100)/PRICING!$D$4+Q15,"") -> 16696.083 | E15: =IF(C15>=1,(K15-C15)*(1+P15*PRICING!$E$4/100)/PRICING!$E$4+Q15,"") -> 9436.9167 | F15: =IF(C15>=1,(K15-C15)*(1+$P15*PRICING!$F$4/100)/PRICING!$F$4+Q15, "") -> 7017.1944 | G15: =IF(C15>=1, (K15-C15)*(1+$P15*PRICING!$G$4/100)/PRICING!$G$4+Q15,"") -> 5807.3333 | H15: =IF(C15>=1, (K15-C15)*(1+$P15*PRICING!$H$4/100)/PRICING!$H$4+Q15, "") -> 5081.4167 | I15: =IF(C15>=1, (K15-C15)*(1+$P15*PRICING!$I$4/100)/PRICING!$I$4+Q15, "") -> 4597.4722 | K15: 87111 | L15: 84668 | M15: =86382+60 -> 86442 | N15: =87196+60 -> 87256 | O15: =87911+60 -> 87971 | P15: 2.5 | S15: 400 | T15: 100
A18: D.Price | B18: BRAND/MODEL | C18: DP | D18: 6 | E18: 12 | F18: 18 | G18: 24 | H18: 30 | I18: 36 | K18: LCP | L18: COD | M18: 30 Days | N18: 60 Days | O18: 90 Days | P18: I.R. ( + ) | S18: Rebate | U18: DATE
A19: KAWASAKI
A20: 55900 | B20: Aura Classic 125 | C20: 1 | D20: =IF(C20>=1,(K20-C20)*(1+P20*$D$2/100)/$D$2+Q20,"") -> 11940.42 | E20: =IF(C20>=1,(K20-C20)*(1+P20*$E$2/100)/$E$2+Q20,"") -> 6880.92 | F20: =IF(C20>=1,(K20-C20)*(1+$P20*$F$2/100)/$F$2+Q20, "") -> 5194.42 | G20: =IF(C20>=1, (K20-C20)*(1+$P20*$G$2/100)/$G$2+Q20,"") -> 4351.17 | H20: =IF(C20>=1, (K20-C20)*(1+$P20*$H$2/100)/$H$2+Q20, "") -> 3845.22 | I20: =IF(C20>=1, (K20-C20)*(1+$P20*$I$2/100)/$I$2+Q20, "") -> 3507.92 | K20: 60715 | L20: 58620 | M20: =60219+60 -> 60279 | N20: =60918+60 -> 60978 | O20: =61515+60 -> 61575 | P20: 3 | S20: 200 | T20: 100
A21: 97000 | B21: Avenger 220 | C21: 1 | D21: =IF(C21>=1,(K21-C21)*(1+P21*$D$2/100)/$D$2+Q21,"") -> 20000.992 | E21: =IF(C21>=1,(K21-C21)*(1+P21*$E$2/100)/$E$2+Q21,"") -> 11304.908 | F21: =IF(C21>=1,(K21-C21)*(1+$P21*$F$2/100)/$F$2+Q21, "") -> 8406.2139 | G21: =IF(C21>=1, (K21-C21)*(1+$P21*$G$2/100)/$G$2+Q21,"") -> 6956.8667 | H21: =IF(C21>=1, (K21-C21)*(1+$P21*$H$2/100)/$H$2+Q21, "") -> 6087.2583 | I21: =IF(C21>=1, (K21-C21)*(1+$P21*$I$2/100)/$I$2+Q21, "") -> 5507.5194 | K21: 104354 | L21: 100489 | M21: 102737 | N21: 104025 | O21: 105214 | P21: 2.5 | S21: 200 | T21: 100
A22: 83900 | B22: Barako 175 Elect./ Barako II | C22: 1 | D22: =IF(C22>=1,(K22-C22)*(1+P22*$D$2/100)/$D$2+Q22,"") -> 17352.35 | E22: =IF(C22>=1,(K22-C22)*(1+P22*$E$2/100)/$E$2+Q22,"") -> 9807.85 | F22: =IF(C22>=1,(K22-C22)*(1+$P22*$F$2/100)/$F$2+Q22, "") -> 7293.0167 | G22: =IF(C22>=1, (K22-C22)*(1+$P22*$G$2/100)/$G$2+Q22,"") -> 6035.6 | H22: =IF(C22>=1, (K22-C22)*(1+$P22*$H$2/100)/$H$2+Q22, "") -> 5281.15 | I22: =IF(C22>=1, (K22-C22)*(1+$P22*$I$2/100)/$I$2+Q22, "") -> 4778.1833 | K22: 90535 | L22: 86440 | M22: =87805+960 -> 88765 | N22: =89170+960 -> 90130 | O22: =90535+860 -> 91395 | P22: 2.5 | S22: 450 | T22: 100
A23: 79900 | B23: Barako 175 Kick | C23: 1 | D23: =IF(C23>=1,(K23-C23)*(1+P23*$D$2/100)/$D$2+Q23,"") -> 16546.392 | E23: =IF(C23>=1,(K23-C23)*(1+P23*$E$2/100)/$E$2+Q23,"") -> 9352.3083 | F23: =IF(C23>=1,(K23-C23)*(1+$P23*$F$2/100)/$F$2+Q23, "") -> 6954.2806 | G23: =IF(C23>=1, (K23-C23)*(1+$P23*$G$2/100)/$G$2+Q23,"") -> 5755.2667 | H23: =IF(C23>=1, (K23-C23)*(1+$P23*$H$2/100)/$H$2+Q23, "") -> 5035.8583 | I23: =IF(C23>=1, (K23-C23)*(1+$P23*$I$2/100)/$I$2+Q23, "") -> 4556.2528 | K23: 86330 | L23: 82235 | M23: =83600+960 -> 84560 | N23: =84965+960 -> 85925 | O23: =86330+860 -> 87190 | P23: 2.5 | S23: 450 | T23: 100
A24: 59000 | B24: Boxer 150 (Boxer) | C24: 1 | D24: =IF(C24>=1,(K24-C24)*(1+P24*$D$2/100)/$D$2+Q24,"") -> 12572.703 | E24: =IF(C24>=1,(K24-C24)*(1+P24*$E$2/100)/$E$2+Q24,"") -> 7245.2867 | F24: =IF(C24>=1,(K24-C24)*(1+$P24*$F$2/100)/$F$2+Q24, "") -> 5469.4811 | G24: =IF(C24>=1, (K24-C24)*(1+$P24*$G$2/100)/$G$2+Q24,"") -> 4581.5783 | H24: =IF(C24>=1, (K24-C24)*(1+$P24*$H$2/100)/$H$2+Q24, "") -> 4048.8367 | I24: =IF(C24>=1, (K24-C24)*(1+$P24*$I$2/100)/$I$2+Q24, "") -> 3693.6756 | K24: 63930 | L24: 63635 | M24: =64633+60 -> 64693 | N24: =64731+60 -> 64791 | O24: =64730+60 -> 64790 | P24: 3 | S24: 350 | T24: 50
A25: 49900 | B25: CT 100 | C25: 1 | D25: =IF(C25>=1,(K25-C25)*(1+P25*$D$2/100)/$D$2+Q25,"") -> 10783.037 | E25: =IF(C25>=1,(K25-C25)*(1+P25*$E$2/100)/$E$2+Q25,"") -> 6213.9533 | F25: =IF(C25>=1,(K25-C25)*(1+$P25*$F$2/100)/$F$2+Q25, "") -> 4690.9256 | G25: =IF(C25>=1, (K25-C25)*(1+$P25*$G$2/100)/$G$2+Q25,"") -> 3929.4117 | H25: =IF(C25>=1, (K25-C25)*(1+$P25*$H$2/100)/$H$2+Q25, "") -> 3472.5033 | I25: =IF(C25>=1, (K25-C25)*(1+$P25*$I$2/100)/$I$2+Q25, "") -> 3167.8978 | K25: 54830 | L25: 54535 | M25: =55534+60 -> 55594 | N25: =55633+60 -> 55693 | O25: =55630+60 -> 55690 | P25: 3 | S25: 500 | T25: 50
A26: 61900 | B26: Curve (SC115A) | C26: 1 | D26: =IF(C26>=1,(K26-C26)*(1+P26*$D$2/100)/$D$2+Q26,"") -> 12784.965 | E26: =IF(C26>=1,(K26-C26)*(1+P26*$E$2/100)/$E$2+Q26,"") -> 7217.382 | F26: =IF(C26>=1,(K26-C26)*(1+$P26*$F$2/100)/$F$2+Q26, "") -> 5361.5209 | G26: =IF(C26>=1, (K26-C26)*(1+$P26*$G$2/100)/$G$2+Q26,"") -> 4433.5904 | H26: =IF(C26>=1, (K26-C26)*(1+$P26*$H$2/100)/$H$2+Q26, "") -> 3876.832 | I26: =IF(C26>=1, (K26-C26)*(1+$P26*$I$2/100)/$I$2+Q26, "") -> 3505.6598 | K26: 66812 | L26: 65539 | M26: 66923 | N26: 67347 | O26: 67672 | P26: 2.17 | Q26: 200 | S26: 200 | T26: 100
A27: 130000 | B27: D Trackers 150 | C27: 1 | D27: =IF(C27>=1,(K27-C27)*(1+P27*$D$2/100)/$D$2+Q27,"") -> 26399.212 | E27: =IF(C27>=1,(K27-C27)*(1+P27*$E$2/100)/$E$2+Q27,"") -> 14720.212 | F27: =IF(C27>=1,(K27-C27)*(1+$P27*$F$2/100)/$F$2+Q27, "") -> 10827.212 | G27: =IF(C27>=1, (K27-C27)*(1+$P27*$G$2/100)/$G$2+Q27,"") -> 8880.7116 | H27: =IF(C27>=1, (K27-C27)*(1+$P27*$H$2/100)/$H$2+Q27, "") -> 7712.8116 | I27: =IF(C27>=1, (K27-C27)*(1+$P27*$I$2/100)/$I$2+Q27, "") -> 6934.2116 | K27: 140149 | L27: 135010 | M27: =137623+60 -> 137683 | N27: =139336+60 -> 139396 | O27: =140949+60 -> 141009 | P27: 2.17 | S27: 350 | T27: 100
A28: 62400 | B28: Fury 125 | C28: 1 | D28: =IF(C28>=1,(K28-C28)*(1+P28*$D$2/100)/$D$2+Q28,"") -> 13337.256 | E28: =IF(C28>=1,(K28-C28)*(1+P28*$E$2/100)/$E$2+Q28,"") -> 7525.3398 | F28: =IF(C28>=1,(K28-C28)*(1+$P28*$F$2/100)/$F$2+Q28, "") -> 5588.0342 | G28: =IF(C28>=1, (K28-C28)*(1+$P28*$G$2/100)/$G$2+Q28,"") -> 4619.3814 | H28: =IF(C28>=1, (K28-C28)*(1+$P28*$H$2/100)/$H$2+Q28, "") -> 4038.1898 | I28: =IF(C28>=1, (K28-C28)*(1+$P28*$I$2/100)/$I$2+Q28, "") -> 3650.7287 | K28: 69744 | L28: 67062 | M28: =68856+60 -> 68916 | N28: =69750+60 -> 69810 | O28: =70544+60 -> 70604 | P28: 2.17 | Q28: 200 | S28: 400 | T28: 100
A29: 115000 | B29: KLX 150 (24 mos. ONLY) | C29: 1 | D29: =IF(C29>=1,(K29-C29)*(1+P29*$D$2/100)/$D$2+Q29,"") -> 22926.783 | E29: =IF(C29>=1,(K29-C29)*(1+P29*$E$2/100)/$E$2+Q29,"") -> 12958.617 | F29: =IF(C29>=1,(K29-C29)*(1+$P29*$F$2/100)/$F$2+Q29, "") -> 9635.8944 | G29: =IF(C29>=1, (K29-C29)*(1+$P29*$G$2/100)/$G$2+Q29,"") -> 7974.5333 | K29: 119619 | L29: 119619 | M29: =120519+60 -> 120579 | N29: =120519+60 -> 120579 | O29: =120419+60 -> 120479 | P29: 2.5 | S29: 200 | T29: 100
A30: 103000 | B30: KSR110 (24 mos. ONLY) 50%DP | C30: 1 | D30: =IF(C30>=1,(K30-C30)*(1+P30*$D$2/100)/$D$2+Q30,"") -> 21364.508 | E30: =IF(C30>=1,(K30-C30)*(1+P30*$E$2/100)/$E$2+Q30,"") -> 12075.592 | F30: =IF(C30>=1,(K30-C30)*(1+$P30*$F$2/100)/$F$2+Q30, "") -> 8979.2861 | G30: =IF(C30>=1, (K30-C30)*(1+$P30*$G$2/100)/$G$2+Q30,"") -> 7431.1333 | K30: 111468 | L30: 108401 | M30: =110323+60 -> 110383 | N30: =111345+60 -> 111405 | O30: =112268+60 -> 112328 | P30: 2.5 | S30: 200 | T30: 100
A31: 77000 | B31: Rouser 150 (NS150) Higher DP NEW | C31: 1 | D31: =IF(C31>=1,(K31-C31)*(1+P31*$D$2/100)/$D$2+Q31,"") -> 15960.275 | E31: =IF(C31>=1,(K31-C31)*(1+P31*$E$2/100)/$E$2+Q31,"") -> 9021.025 | F31: =IF(C31>=1,(K31-C31)*(1+$P31*$F$2/100)/$F$2+Q31, "") -> 6707.9417 | G31: =IF(C31>=1, (K31-C31)*(1+$P31*$G$2/100)/$G$2+Q31,"") -> 5551.4 | H31: =IF(C31>=1, (K31-C31)*(1+$P31*$H$2/100)/$H$2+Q31, "") -> 4857.475 | I31: =IF(C31>=1, (K31-C31)*(1+$P31*$I$2/100)/$I$2+Q31, "") -> 4394.8583 | K31: 83272 | L31: 80159 | M31: =81196+960 -> 82156 | N31: =82234+960 -> 83194 | O31: =83272+860 -> 84132 | P31: 2.5 | S31: 350 | T31: 100
A32: 69500 | B32: Rouser 180 | C32: 1 | D32: =IF(C32>=1,(K32-C32)*(1+P32*$D$2/100)/$D$2+Q32,"") -> 14672.275 | E32: =IF(C32>=1,(K32-C32)*(1+P32*$E$2/100)/$E$2+Q32,"") -> 8293.025 | F32: =IF(C32>=1,(K32-C32)*(1+$P32*$F$2/100)/$F$2+Q32, "") -> 6166.6083 | G32: =IF(C32>=1, (K32-C32)*(1+$P32*$G$2/100)/$G$2+Q32,"") -> 5103.4 | H32: =IF(C32>=1, (K32-C32)*(1+$P32*$H$2/100)/$H$2+Q32, "") -> 4465.475 | I32: =IF(C32>=1, (K32-C32)*(1+$P32*$I$2/100)/$I$2+Q32, "") -> 4040.1917 | K32: 76552 | L32: 73792 | M32: 75672 | N32: 76592 | O32: 77412 | P32: 2.5 | S32: 350 | T32: 50
